Workbook

Sheet 의사결정요약
A1: 한전 전기요금 2026 — HEMS 의사결정 요약
A2: 기준일 2026-09-15 · 셀 색상: 흰색=확정(1차·요금표 근거) / 노랑=추정·산출 / 주황=확인필요 · 출처ID는 '출처' 시트 참조 (A1=약관, A2=시행세칙)
A4: 결론 1. 육지/제주는 분리해야 하는가? → '단가표'는 1벌, '시간대·선택요금제·인센티브'는 지역별로 분리
A5: 한전 기본·전력량 단가는 전국 단일 요금표이므로 단가 DB를 지역별로 따로 둘 필요는 없다(S05). 그러나 계시별 시간대 정의(제주는 2021.9부터 최대부하 16~22시, 육지는 2026.4.16 개편으로 평일 15~21시), 주택용 계시별 선택요금 가입 자격(제주는 주거용 전 가구, 육지는 인증 지열·공기열 설비 설치 가구만 — 세칙 제48조의5), 산업용 지역별 차등요금(제주 제외)이 다르다. 플러스DR은 2024.3 육지에도 신설되어 제주 전용이 아니며(S32), 시장만 육지권/제주권으로 분리 운영된다. 따라서 HEMS 스케줄러는 '지역' 파라미터로 시간대 테이블과 적용 가능 요금제를 분기하는 구조가 맞다.
A7: 비교 항목 | B7: 육지 | C7: 제주 | D7: 차이 | E7: HEMS 시사점 | F7: 근거 / 상태
A8: 기본·전력량 단가표 | B8: 전국 단일 요금표 | C8: 동일 | D8: 동일 | E8: 단가 DB는 1벌로 관리 | F8: S05 / 확정
A9: 주택용 누진제(기본값) | B9: 적용 (저압 200/400kWh, 하계 300/450kWh 경계) | C9: 동일 | D9: 동일 | E9: 누진구간 관리 로직은 공통 | F9: S05 / 확정
A10: 주택용 계시별 선택요금 | B10: 인증 지열·공기열 설비 설치 주거용 고객만 선택 가능 (2026.4.1~; 해당 설비에 일반용 별도 적용 중이면 제외) | C10: 주거용 전 가구 선택 가능 (2021.9.1~, 세칙 부칙 2021.6.25) | D10: 다름 | E10: 제주 가구는 부하이동(시간대 최적화)으로 요금 절감 가능 → HEMS 가치가 가장 큰 지역 | F10: A2 제48조의5 / 확정
A11: 계시별 최대부하 시간(평일) — 계시별 적용 종별만 | B11: 여름·봄·가을 15~21시 / 겨울 09~12시·16~19시 | C11: 16~22시 (모든 계절) | D11: 다름 | E11: 시간대 테이블을 지역별로 분리. 육지는 계절 분기까지 필요, 제주는 계절 무관 단일. 단, 지역만으로 적용 금지 — 계약종별·선택요금제까지 확인(주택용 누진제는 시간대 없음) | F11: A1 별표3 / 확정
A12: 계시별 중간부하(낮) | B12: 여름·봄·가을 08~15시·21~22시 / 겨울 08~09·12~16·19~22시 | C12: 08~16시 | D12: 다름 | E12: 낮 시간 태양광 잉여 흡수 구간은 두 지역 모두 '중간부하' | F12: A1 별표3 / 확정
A13: 경부하 | B13: 22~08시 (전 계절) | C13: 22~08시 (전 계절) | D13: 동일 | E13: 야간 충전·축열 전략은 공통 | F13: A1 별표3 / 확정
A14: 토요일·공휴일 계량 특례 | B14: 공휴일은 전 시간 경부하 계량, 토요일 최대부하는 중간부하로 계량 | C14: 동일 (별표3 본문 단서 공통 적용) | D14: 동일 | E14: 주말 스케줄러는 평일 시간대표를 그대로 쓰면 안 됨 | F14: A1 별표3 단서1 / 확정
A15: 봄·가을 주말·공휴일 11~14시 50% 할인 | B15: 주말 할인요금(약관 제67조의7·세칙 제48조의7), 2026.4.16~2030.12.31, 3년마다 연장 검토. 대상은 산업용(을)·전기자동차 충전전력 고객만 | C15: 세칙 제48조의7에 지역 제한 없음 → 적용 | D15: 동일 | E15: 주택용(누진·계시별 모두)은 대상이 아님 → 주택 HEMS에서는 EV 별도계약 고객의 충전 스케줄에만 반영 | F15: A2 제48조의7 / 확정
A16: 2026 계시별 개편 시간대의 제주 적용 | B16: 적용 | C16: 미적용 — 2026.8.1 약관에도 제주 단서(22~08/08~16/16~22) 그대로 유지 | D16: 다름 | E16: 제주는 개편 영향 없음이 약관으로 확정됨 | F16: A1 별표3 단서4 / 확정
A17: 산업용 지역별 차등요금 | B17: 2026년 내 도입 예정, 11개 지역·최대 18원/kWh 인하 | C17: 적용 제외 | D17: 다름 | E17: 주택용은 대상 아님 → 주택 HEMS 직접 영향 없음 | F17: S16·S17 / 확정(발표 기준)
A18: DR·인센티브 | B18: 에너지캐시백(2026.7~ 확대), 국민DR(89,973고객), 플러스DR(2024.3 육지 신설, 43,061고객) → 상세 DR_수요반응 시트 | C18: 동일 (플러스DR은 2021.1 제주 신설, 2022.5 제주 수요자원시장 분리 운영) | D18: 동일 (DR 시장만 육지권/제주권 분리) | E18: 양 지역 모두 '더 쓰면 보상' 신호 반영 가능. 가구 실수령 단가는 집합사업자 계약·시장정산에 따르므로 공통값 없음 | F18: S20·S25·S32 / 확정(시장 존재 기준), 정산조건은 사업자별
... A21: ESS 요금 특례 | B21: 주택용 없음. 계시별 일반·산업·교육용 대상 기본요금 할인(2016.4.1~2026.3.31 종료) | C21: 동일 | D21: 동일 | E21: 주택 ESS 가치는 요금특례가 아니라 누진회피·계시별 차익·캐시백에서 발생 | F21: A2 별표4 제9호 / 확정(종료)
A23: 결론 2. HEMS 대상 고객유형별 적용 가능 요금제와 최적화 목표
A24: 고객 유형 | B24: 적용 가능 요금제 | C24: 요금 절감 레버 | D24: HEMS 최적화 목표(권장) | E24: 주의점 | F24: 근거
A25: 육지 일반 주택(저압) | B25: 주택용 누진제만 | C25: 월 누적 사용량(누진구간). 시간대 이동은 요금 효과 없음 | D25: 월간 사용량 예측 → 200/400kWh(하계 300/450) 경계 초과 방지. 2026.7~8 저녁 17~20시 절감 캐시백(최대 500원/kWh) 대응 | E25: 2026 계시별 개편은 주택용 누진 고객에 적용 안 됨 | F25: S05·S20·S27
A26: 육지 히트펌프 설치 가구 | B26: ① 누진제 ② 히트펌프 전력만 일반용 분리 ③ 주택용 계시별 (2026.4.1~ 선택) | C26: 요금제 선택 자체 + 시간대 이동 | D26: 월 사용량 약 600kWh 이상이면 ② 분리요금이 유리하다는 분석 → 요금제 추천 로직 필요. ③ 선택 시 기본요금 월 12,930원(4,310원/kW×3kW) 고정비 반영 | E26: 신재생에너지법 제13조 인증 지열·공기열 설비 설치 주거용 고객. 공기열은 인증심사기준 마련 전까지 기후부 선정·공지 제품을 인증 간주(약관 부칙). 비주거용, 시간대 계량 불가, 누진 복귀 후 1년 미경과 가구는 제외. 계시별 변경 후 1년간 누진 복귀 불가 | F26: A2 제48조의5·S14·S15
A27: 제주 주택 | B27: ① 누진제 ② 주택용 계시별 선택 (2021.9~) | C27: 계시별 선택 시 16~22시 회피, 22~08·08~16시로 이동 | D27: 계시별 가입 가구: 최대부하(16~22) 회피 스케줄링. 미가입 가구: 누진 관리 + 계시별 전환 시뮬레이션 제공 | E27: 계시별 기본요금은 4,310원/kW × 요금적용전력 3kW/가구 = 월 12,930원(세칙 별표12)으로 누진 기본요금(910~7,300원)보다 월 5,630~12,020원 높음 → 저사용 가구는 불리. 저압 9월 야간집중(경70/중20/최10%) 기준 손익분기 약 385kWh/월. 6~8월·11~2월 1,000kWh 초과분은 736.2원/kWh 슈퍼유저 단가 | F27: A2 별표12·제48조의5 / 확정
A28: EV 자가충전(주택·아파트) | B28: 전기자동차 충전전력요금(계시별, 별도 계약) 또는 주택용에 합산 | C28: 경부하(22~08) 충전, 봄·가을 주말·공휴일 11~14시 50% 할인 | D28: 충전 스케줄: 평일 경부하 우선, 봄·가을 주말 낮 할인창 활용 | E28: 2022.7 특례할인 폐지 후 기본요금 정상 부과 | F28: A2 별표4 제4호·S03·S22
A29: ESS 보유 가구 | B29: 주택용 ESS 전용 요금할인 없음 | C29: 태양광 잉여 저장·자가소비(순 수전량 감소), (계시별 가입 시) 경부하 충전→최대부하 방전 차익, 캐시백·DR | D29: 누진 고객: 계통 충전→방전은 같은 검침월의 누적 kWh를 줄이지 못하고 손실만 늘리므로 태양광 연계 시에만 누진구간 관리 효과 / 계시별 고객: 시간대 차익 운전 | E29: 피크저감 ESS 특례는 일반·산업·교육용 계시별 고객 대상이며 2026.3.31 종료됨(2026.8.1판 세칙에도 연장 없음). 할인 수익을 사업성에 넣지 말 것 | F29: A2 별표4 제9호·S18·S19·S26
A31: 결론 3. 2026년 요금 변동 요약 (무엇이 바뀌었고 무엇이 그대로인가)
A32: 항목 | B32: 2026년 상태 | C32: 시행일 | D32: 적용 대상 | E32: 비고 | F32: 근거
A33: 주택용 누진 단가 | B33: 동결 (2023.5 이후 13분기 연속) | C33: - | D33: 주택용 | F33: S08
A34: 연료비조정단가 | B34: +5.0원/kWh 유지 | C34: 2026 3분기 | D34: 전 종별 | E34: 상한 적용 지속 | F34: S07
A35: 산업용 기본 단가 | B35: 2024.10.24 인상분 유지 (을 +16.9, 갑 +8.5원/kWh) | C35: 2024.10.24 | D35: 산업용 | E35: 2025.04 요금표에 반영됨 | F35: S05
A36: 계시별 시간대 개편 | B36: 평일 11~15시 최대→중간, 18~21시 중간→최대 | C36: 2026.4.16 / 6.1 | D36: 산업용(을)·EV / 산업용(갑)Ⅱ·일반용(갑)Ⅱ·(을)·교육용(을) | E36: 산업용(을) 유예 514곳은 10.1 적용 | F36: S01·S02·S04
A37: 계시별 단가 조정 | B37: 경부하 +5.1원, 최대부하 -16.9원(여름·겨울) / -13.2원(봄·가을). 별표1에 반영 완료 | C37: 2026.4.16 | D37: 산업용(을)만 | E37: 유예 고객은 역산식으로 개편 전 수준 적용(부칙 제4호). 일반용·산업용(갑)Ⅱ·교육용은 단가 변동 없이 시간대만 개편 | F37: A1 별표1·부칙
A38: 일반용(갑)Ⅱ 선택Ⅲ·Ⅳ 신설 | B38: 계시별 대신 계절별 단일요금 선택 가능(갑Ⅰ과 동일 단가) | C38: 2026.6.1 | D38: 일반용(갑)Ⅱ | E38: 6~11월분은 기존 선택과 자동 비교해 유리한 쪽 적용, 신청분은 12월분부터 | F38: A1 별표1·부칙 2026.5.22
A39: 봄·가을 주말·공휴일 할인 | B39: 11~14시 전력량요금 50% | C39: 2026.4.16 (EV 4.18) | D39: 산업용(을)·전기자동차 충전전력만 (세칙 제48조의7 ①). 일반용·교육용·산업용(갑)Ⅱ·주택용 계시별은 대상 아님 | E39: 2030.12.31까지 | F39: A2 제48조의7·S03
A40: 주택용 히트펌프 요금 선택 | B40: 3개 요금제 중 선택 | C40: 2026.4.1 | D40: 육지 인증 지열·공기열 설비 설치 가구 | F40: A2 제48조의5·S15
A41: 에너지캐시백 확대 | B41: 1% 절감부터 최대 120원/kWh, 여름 저녁 피크 최대 500원/kWh, 스마트가전 100원/kWh | C41: 2026.7~12 | D41: 주택용 | F41: S20
A42: 산업용 지역별 차등요금 | B42: 11개 지역, 최대 18원/kWh 인하 | C42: 2026년 내 예정 | D42: 산업용(제주 제외) | E42: 주택용 제외 | F42: S16
A43: 전력산업기반기금 | B43: 2.7% | C43: 2025.7~ | D43: 전 종별 | F43: S09
A45: ※ 2026-09-15 개정: 한전 기본공급약관(2026.8.1, 프로젝트 문서 A1) 원문을 1순위 근거로 재검증했다. 이전 버전에서 추정·확인필요로 두었던 항목 중 ① 개편 후 겨울 시간대(기존 유지) ② 제주 시간대 유지 ③ 토요일·공휴일 계량 특례 ④ 산업용(을) 개편 후 단가 ⑤ 기후환경요금 9.0원 은 모두 약관 원문으로 확정 처리했다. 남은 확인필요는 주택용 계시별 선택요금의 기본요금 단위(원/호 vs 원/kW), EV 충전전력 단가, 심야전력 단가, ESS 특례 존속 여부 — 모두 시행세칙 소관이며 이 PDF에는 세칙 본문이 없다.
A46: ※ 2026-09-15 _5 개정: 한전 기본공급약관 시행세칙(2026.8.1판, 232쪽, 출처 A2)과 전력거래소 2026 사업실명제 내역서(S32) 원문으로 재검증. ① 주택용 계시별 기본요금 = 4,310원/kW × 요금적용전력 3kW = 월 12,930원 확정(별표12, 이전 '원/호' 가설 폐기) ② 계시별 봄·가을 단가 125.8/153.8/172.4 및 슈퍼유저(6~8월·11~2월 1,000kWh 초과 736.2원/kWh) 확정 ③ 육지 계시별 가구의 시간대는 약관 별표3 제1호 준용(제48조의5 ⑤) → 2026 개편 시간대 적용 ④ 주말 할인요금 대상은 산업용(을)·EV 충전전력만(제48조의7 ①) ⑤ 플러스DR은 2024.3 육지에도 신설(제주 전용 아님) ⑥ ESS 요금특례 2026.3.31 종료 확정(별표4 제9호) ⑦ EV 충전전력 단가는 세칙 별표4 제4호 원문과 일치 → 확정 ⑧ 계시별 가입자격 = 인증 지열·공기열 설비 설치 주거용(제48조의5) ⑨ 계통 충전 ESS로는 누진 회피 불가 ⑩ 심야전력은 선택공급약관 소관(세칙에도 단가표 없음). 남은 확인필요: 심야전력 현행 단가·가입조건, 산업용 지역차등 확정본, 2026 4분기 연료비조정단가.
A47: ※ 2026-09-15 _6 개정 (검증본 재검토판과 대조): ⑪ 일반용 보완전력 6행은 현행 약관·세칙에 항목이 없어(선택공급약관 소관) 확정→확인필요로 하향 ⑫ 여름 저녁 피크 캐시백에 월 지급한도 10,000원 추가(세칙 제48조의6) ⑬ 공기열 인증 경과조치(인증심사기준 마련 전 기후부 선정·공지 제품 인증 간주, 약관 부칙 2026.3.16) 반영 ⑭ 2021~2026.3 ESS 구 할인 유지 예외(손실보전위원회 의결 대상) 주석.
...

Sheet 변경이력
A1: 변경이력 | B1: 현재 버전 | C1: v12 | D1: 기준일 | E1: 2026-09-15
A2: 파일명은 고정(한전_전기요금_2026_HEMS정리.xlsx). 버전은 이 시트 C1이 기준이며 현황판 상단 표기도 여기서 읽는다. 과거본은 archive/날짜_vN.xlsx로 보관. 규칙: 셀 값을 바꾸면 반드시 이 표에 한 줄 추가(변경 전·후 값 포함), 시트 구조 변경(행 삽입·시트 삭제) 금지.
A4: 버전 | B4: 일자 | C4: 시트!셀 | D4: 변경 전 | E4: 변경 후 | F4: 사유·근거 | G4: 출처ID | H4: 변경자 | I4: 승인
A5: v12 | B5: 2026-09-15 | C5: (기준선) | D5: — | E5: 파일명 고정(한전_전기요금_2026_HEMS정리.xlsx) · 변경이력 관리 시작 | F5: v12 이전 개정 내용은 의사결정요약 A45~A52 참조. 이후 모든 셀 변경은 이 표에 기록 | G5: — | H5: Claude | I5: 사용자

Sheet 계약종별_쉬운설명
A1: 계약종별 쉬운 설명 — HEMS 관점에서 알아야 할 요금제만
A2: 갑·을, Ⅰ·Ⅱ, 선택Ⅰ~Ⅳ, 고압A/B 같은 기호를 먼저 풀고, HEMS가 실제로 다루는 종별(주택용·일반용·EV)을 한 표로 비교합니다. 산업용·교육용·농사용·가로등·심야는 HEMS 범위 밖이라 시트를 숨김 처리했습니다(삭제 아님, 시트 탭 우클릭 → 숨기기 취소).
A4: A. 기호 풀이 — 종별 이름을 읽는 법
A5: 기호 | B5: 뜻 | C5: 쉽게 말하면 | D5: 어디서 정하나 | E5: 비고
A6: 갑 / 을 | B6: 계약전력(계약한 최대 사용 규모, kW)으로 나눈 등급 | C6: 갑 = 작은 곳(300kW 미만), 을 = 큰 곳(300kW 이상). 교육용만 기준이 1,000kW | D6: 약관 제57~59조 | E6: 주택은 갑·을 구분 없음
A7: 갑Ⅰ / 갑Ⅱ | B7: 갑 안에서 요금 계산 방식으로 나눈 것 | C7: 갑Ⅰ = 계절만 보고 단가 1개(계절별 단일요금). 갑Ⅱ = 시간대별 계량기를 달아 경·중·최대부하로 나눠 계산(계시별) | D7: 약관 별표1 | E7: 갑Ⅱ가 되려면 시간대별 전력량계 설치. 을은 항상 계시별
A8: 선택Ⅰ·Ⅱ·Ⅲ(·Ⅳ) | B8: 기본요금과 전력량요금의 조합 옵션 | C8: 번호가 올라갈수록 기본요금(원/kW)은 비싸지고 전력량단가(원/kWh)는 싸진다 → 전기를 많이·꾸준히 쓰는 곳일수록 높은 번호가 유리 | D8: 약관 별표1 | E8: 일반용(갑)Ⅱ의 선택Ⅲ·Ⅳ만 예외: 계시별을 포기하고 갑Ⅰ과 같은 계절별 단일요금을 쓰는 옵션(2026.6.1 신설)
A9: 저압 / 고압A / 고압B / 고압C | B9: 공급받는 전압 | C9: 저압 = 220/380V(일반 주택·소규모 상가). 고압A = 3.3~66kV(대부분의 건물·아파트 수전). 고압B = 154kV, 고압C = 345kV(대형 공장급) | D9: 약관 제23조 | E9: 전압이 높을수록 단가가 조금 싸다(한전 설비 부담이 적어서). 아파트는 단지가 고압으로 받아도 세대 청구는 주택용 고압 누진
A10: 경부하 / 중간부하 / 최대부하 | B10: 하루를 3구간으로 나눈 시간대 | C10: 경 = 밤(22~08시, 제일 싸다), 중간 = 낮, 최대 = 저녁 피크(제일 비싸다). 구간 경계는 계절·지역에 따라 다름 → 시간대_육지vs제주 시트 | D10: 약관 별표3 | E10: 2026 개편으로 육지 여름·봄·가을 최대부하가 15~21시로 이동
A11: 계시별 (계절별·시간대별) | B11: 계절 × 시간대로 단가가 달라지는 요금 | C11: "언제 쓰느냐"에 따라 요금이 달라지는 방식. HEMS가 부하 이동으로 돈을 아낄 수 있는 요금제는 전부 계시별 | D11: 약관 별표1·별표3 | E11: 누진제(주택 기본)는 "얼마나 쓰느냐"만 본다 → 시간 이동 효과 없음
A12: 누진제 | B12: 월 사용량이 많아질수록 단가가 올라가는 구조(3단계) | C12: 200kWh까지 120원, 다음 200kWh 214.6원, 400kWh 초과 307.3원. 기본요금도 도달 단계에 따라 910 → 1,600 → 7,300원 | D12: 약관 별표1 1.가 | E12: 여름(7~8월)은 구간이 300/450kWh로 넓어짐. 1,000kWh 초과는 슈퍼유저 736.2원
A13: 기본요금 단위 | B13: 원/kW 또는 원/호 | C13: 원/호 = 집 한 채당 정액(주택 누진). 원/kW = 계약전력(또는 요금적용전력) 1kW마다 부과(일반·산업·EV·주택 계시별) | D13: 약관 별표1, 세칙 별표12 | E13: 주택용 계시별 선택요금은 원/kW(4,310원) × 3kW 고정 = 월 12,930원
A14: 요금적용전력 | B14: 기본요금을 곱할 kW | C14: 보통은 계약전력. 최대수요전력계가 있으면 직전 12개월 중 여름·겨울 피크 중 최댓값(계약전력의 30% 이상) | D14: 약관 제68조 | E14: EV 별도계약의 K값이 이것. 충전기 명판 7kW와 다를 수 있음
A16: B. HEMS가 다루는 계약종별 비교
A17: 구분 | B17: 주택용 (누진제) | C17: 주택용 계시별 선택요금 | D17: 일반용(갑)Ⅰ | E17: 일반용(갑)Ⅱ 선택Ⅰ·Ⅱ | F17: 일반용(갑)Ⅱ 선택Ⅲ·Ⅳ | G17: 일반용(을) | H17: 전기자동차 충전전력
A18: 계약전력 | B18: 주거용 (원칙 3kW 이하 소규모 포함) | C18: 주거용 + 자격요건 | D18: 300kW 미만 | E18: 300kW 미만 | F18: 300kW 미만 | G18: 300kW 이상 | H18: 충전설비 용량 기준 별도 계약
A19: 주요 고객 (설명) | B19: 일반 가정·아파트 세대 | C19: 제주 주거용 전 가구 / 육지 인증 지열·공기열(히트펌프) 설치 가구 | D19: 소규모 상가·사무실·소형 건물 | E19: 중소형 상가·빌딩·사업장 (시간대별 계량기 설치) | F19: 갑Ⅱ 고객 중 시간 이동이 어려운 곳 | G19: 대형 빌딩·호텔·백화점·대형 사업장 | H19: 자택·아파트 자가충전기, 충전사업자
A20: 요금 방식 | B20: 누진 3단계 (얼마나 쓰느냐) | C20: 경·중·최대부하 시간대별 (언제 쓰느냐) | D20: 계절별 단일요금 | E20: 경·중·최대부하 시간대별 | F20: 계절별 단일요금 (갑Ⅰ과 동일 단가) | G20: 경·중·최대부하 시간대별 | H20: 경·중·최대부하 시간대별
A21: 계시별 적용 | B21: ✕ 없음 | C21: ○ | D21: ✕ 없음 | E21: ○ | F21: ✕ (계시별 포기 옵션) | G21: ○ (필수) | H21: ○
A22: 선택 종류 | B22: 없음 (저압/고압만 다름) | C22: 없음 | D22: 저압 / 고압A·B 선택Ⅰ·Ⅱ | E22: 선택Ⅰ·Ⅱ | F22: 선택Ⅲ·Ⅳ (2026.6.1 신설) | G22: 선택Ⅰ·Ⅱ·Ⅲ | H22: 자가소비용 저압/고압 (사업자용은 선택Ⅰ~Ⅳ)
A23: 기본요금 | B23: 910 / 1,600 / 7,300 원/호 (도달 단계) | C23: 4,310원/kW × 3kW = 12,930원/월 고정 | D23: 저압 6,160 · 고압A 7,170(Ⅰ)/8,230(Ⅱ) 원/kW | E23: 고압A 7,170(Ⅰ)/8,230(Ⅱ) 원/kW | F23: 고압A 7,170(Ⅲ)/8,230(Ⅳ) 원/kW | G23: 고압A 7,220(Ⅰ)/8,320(Ⅱ)/9,810(Ⅲ) 원/kW | H23: 저압 2,390 · 고압 2,580 원/kW
A24: 최대부하 단가 (봄·가을, 고압A 선택Ⅰ 기준) | B24: 해당 없음 (구간단가 120/214.6/307.3) | C24: 172.4 원/kWh | D24: 해당 없음 (98.6 단일) | E24: 108.1 원/kWh | F24: 해당 없음 (98.6 단일) | G24: 146.0 원/kWh — 갑Ⅱ보다 높아 피크 관리가 더 중요 | H24: 저압 102.1 · 고압 94.9 원/kWh
A25: 경부하 단가 (봄·가을) | B25: — | C25: 125.8 | D25: — | E25: 89.4 (고압A Ⅰ) | F25: — | G25: 92.8 (고압A Ⅰ) | H25: 저압 85.4 · 고압 80.2
A26: 2026 시간대 개편 적용일 | B26: 해당 없음 | C26: 별표3 준용 (육지 6.1 개편 시간대, 제주 16~22시) | D26: 해당 없음 | E26: 2026.6.1 | F26: 해당 없음 | G26: 2026.6.1 | H26: 2026.4.16
A27: 봄·가을 주말 11~14시 50% 할인 | B27: ✕ | C27: ✕ | D27: ✕ | E27: ✕ | F27: ✕ | G27: ✕ | H27: ○ (2026.4.18~2030.12.31)
A28: HEMS에서 쓸 수 있는 레버 | B28: 월 누적 사용량 관리 (400kWh·1,000kWh 경계), 캐시백 | C28: 부하 이동 (최대부하 회피), 누진 vs 계시별 전환 시뮬레이션 | D28: 사용량 절감만 | E28: 부하 이동, 선택Ⅰ↔Ⅱ 비교 | F28: 사용량 절감만 | G28: 부하 이동 + 최대수요(kW) 관리, 선택Ⅰ~Ⅲ 비교 | H28: 야간 충전, 봄·가을 주말 낮 충전, 별도계약 vs 합산 비교
A29: 근거 | B29: A1 별표1 1.가 | C29: A2 별표12·제48조의5 | D29: A1 별표1 1.나 | E29: A1 별표1 1.나 | F29: A1 별표1·부칙 2026.5.22 | G29: A1 별표1 1.나 | H29: A2 별표4 제4호·제48조의7
A30: "주요 고객" 행은 이해를 돕기 위한 일반적 설명이며 약관에 규정된 문구가 아닙니다. 나머지 행은 약관·시행세칙 원문 기준(출처 시트 A1·A2). 단가는 2026.6.1 시행 별표1, 주택 계시별·EV는 2026.8.1판 시행세칙.
A32: C. 선택Ⅰ vs 선택Ⅱ — 어느 쪽이 유리한가 (일반용(갑)Ⅱ 고압A 예시)
A33: 항목 | B33: 선택Ⅰ | C33: 선택Ⅱ | D33: 차이 | E33: 해석
A34: 기본요금 (원/kW·월) | B34: 7,170 | C34: 8,230 | D34: +1,060 | E34: Ⅱ가 kW당 1,060원 더 냄
A35: 전력량요금 봄·가을 (경/중/최, 원/kWh) | B35: 89.4 / 96.8 / 108.1 | C35: 84.1 / 91.5 / 102.8 | D35: −5.3 (전 시간대 동일) | E35: Ⅱ가 kWh당 5.3원 덜 냄
A36: 손익분기 | B36: — | C36: — | D36: 1,060 ÷ 5.3 = 200 kWh/kW·월 | E36: 계약전력 1kW당 월 200kWh 이상(이용률 약 28%) 쓰면 선택Ⅱ 유리. 예: 100kW 계약이면 월 20,000kWh 이상
A37: 일반용(을)의 선택Ⅲ | B37: 기본 9,810 (Ⅰ 대비 +2,590) | C37: 전력량 Ⅰ 대비 약 −6.4~−13.8원 | D37: 봄·가을 최대부하 기준 −13.8 | E37: 을 고객은 Ⅰ→Ⅱ→Ⅲ으로 갈수록 대형·고이용률 사업장용
A38: 원리: 선택 번호는 "고정비를 더 내고 변동비를 깎는" 옵션입니다. 이용률(사용량 ÷ 계약전력)이 높을수록 높은 번호가 유리합니다. 주택용·EV 자가소비에는 선택 옵션이 없습니다.
A40: D. HEMS 범위 밖 종별 (참고만)
A41: 종별 | B41: 한 줄 설명 | C41: HEMS 관련성 | D41: 시트
A42: 산업용(갑Ⅰ·갑Ⅱ·을) | B42: 광업·제조업. 구조는 일반용과 같고(갑/을·선택·계시별) 단가만 다름. 을은 2026.4.16 개편·9.30까지 유예·주말 50% 할인 대상 | C42: 가정 HEMS 없음. 공장 EMS 대상 | D42: 산업용 (숨김)
A43: 교육용(갑·을) | B43: 학교·도서관. 갑/을 기준이 1,000kW | C43: 없음 | D43: 교육용 (숨김)
A44: 농사용·가로등·심야전력 | B44: 단일요금 종별. 심야전력은 신규가입 중단, 현행 단가 미확인 | C44: 없음 (심야 축열기기 가구는 예외적) | D44: 농사용_가로등_심야 (숨김)
...

Sheet 시간대_육지vs제주
A1: 계시별 시간대 구분 — 육지 vs 제주 (24시간)
A2: 초록=경부하 / 노랑=중간부하 / 빨강=최대부하 / 파랑=봄·가을 주말·공휴일 50% 할인 / 회색=근거 미확보
A3: 주의: 아래 육지 시간대는 계시별 요금제를 적용받는 계약종별에만 해당합니다. 일반 주택용 누진제·일반용(갑)Ⅰ·일반용(갑)Ⅱ 선택Ⅲ·Ⅳ·산업용(갑)Ⅰ·교육용(갑)·농사용·가로등에는 적용되지 않습니다. HEMS는 지역 + 계약종별 + 선택요금제를 함께 확인한 뒤 시간대를 적용할 것.
A4: 구분 | B4: 적용 기간·대상 | C4: 00 | D4: 01 | E4: 02 | F4: 03 | G4: 04 | H4: 05 | I4: 06 | J4: 07 | K4: 08 | L4: 09 | M4: 10 | N4: 11 | O4: 12 | P4: 13 | Q4: 14 | R4: 15 | S4: 16 | T4: 17 | U4: 18 | V4: 19 | W4: 20 | X4: 21 | Y4: 22 | Z4: 23 | AA4: 근거 | AB4: 상태
A5: 육지 계시별 적용 종별 (개편 전) — 여름·봄·가을 | B5: ~2026.4.15 (일반·교육용 등은 ~5.31). 산업용(을) 유예 신청 고객은 ~2026.9.30까지 이 시간표 유지. 주택용 누진제는 제외 | C5: 경 | D5: 경 | E5: 경 | F5: 경 | G5: 경 | H5: 경 | I5: 경 | J5: 경 | K5: 중 | L5: 중 | M5: 중 | N5: 최 | O5: 중 | P5: 최 | Q5: 최 | R5: 최 | S5: 최 | T5: 최 | U5: 중 | V5: 중 | W5: 중 | X5: 중 | Y5: 경 | Z5: 경 | AA5: S13·S06 | AB5: 확정
A6: 육지 계시별 적용 종별 (개편 전) — 겨울 | B6: ~2026.4.15 (일반·교육용 등은 ~5.31). 산업용(을) 유예 고객 ~9.30. 주택용 누진제는 제외 | C6: 경 | D6: 경 | E6: 경 | F6: 경 | G6: 경 | H6: 경 | I6: 경 | J6: 경 | K6: 중 | L6: 최 | M6: 최 | N6: 최 | O6: 중 | P6: 중 | Q6: 중 | R6: 중 | S6: 최 | T6: 최 | U6: 최 | V6: 중 | W6: 중 | X6: 중 | Y6: 경 | Z6: 경 | AA6: S13 | AB6: 확정
A7: 육지 계시별 적용 종별 — 평일 여름 | B7: 적용 종별: 산업용(을)·전기자동차 충전전력 2026.4.16~ / 일반용(갑)Ⅱ 선택Ⅰ·Ⅱ, 일반용(을), 산업용(갑)Ⅱ, 교육용(을) 2026.6.1~ / 주택용 계시별 선택요금 가입자(육지는 인증 지열·공기열 설치 주거용만). 제외: 일반 주택용 누진제, 일반용(갑)Ⅰ, 일반용(갑)Ⅱ 선택Ⅲ·Ⅳ(계절별 단일), 산업용(갑)Ⅰ, 교육용(갑), 농사용·가로등 | C7: 경 | D7: 경 | E7: 경 | F7: 경 | G7: 경 | H7: 경 | I7: 경 | J7: 경 | K7: 중 | L7: 중 | M7: 중 | N7: 중 | O7: 중 | P7: 중 | Q7: 중 | R7: 최 | S7: 최 | T7: 최 | U7: 최 | V7: 최 | W7: 최 | X7: 중 | Y7: 경 | Z7: 경 | AA7: A1 별표3 | AB7: 확정
A8: 육지 계시별 적용 종별 — 평일 봄·가을 | B8: 적용 종별: 산업용(을)·전기자동차 충전전력 2026.4.16~ / 일반용(갑)Ⅱ 선택Ⅰ·Ⅱ, 일반용(을), 산업용(갑)Ⅱ, 교육용(을) 2026.6.1~ / 주택용 계시별 선택요금 가입자(육지는 인증 지열·공기열 설치 주거용만). 제외: 일반 주택용 누진제, 일반용(갑)Ⅰ, 일반용(갑)Ⅱ 선택Ⅲ·Ⅳ(계절별 단일), 산업용(갑)Ⅰ, 교육용(갑), 농사용·가로등 | C8: 경 | D8: 경 | E8: 경 | F8: 경 | G8: 경 | H8: 경 | I8: 경 | J8: 경 | K8: 중 | L8: 중 | M8: 중 | N8: 중 | O8: 중 | P8: 중 | Q8: 중 | R8: 최 | S8: 최 | T8: 최 | U8: 최 | V8: 최 | W8: 최 | X8: 중 | Y8: 경 | Z8: 경 | AA8: A1 별표3 | AB8: 확정
A9: 육지 계시별 적용 종별 — 평일 겨울 | B9: 적용 종별: 산업용(을)·전기자동차 충전전력 2026.4.16~ / 일반용(갑)Ⅱ 선택Ⅰ·Ⅱ, 일반용(을), 산업용(갑)Ⅱ, 교육용(을) 2026.6.1~ / 주택용 계시별 선택요금 가입자(육지는 인증 지열·공기열 설치 주거용만). 제외: 일반 주택용 누진제, 일반용(갑)Ⅰ, 일반용(갑)Ⅱ 선택Ⅲ·Ⅳ(계절별 단일), 산업용(갑)Ⅰ, 교육용(갑), 농사용·가로등 (겨울 시간대는 개편 전과 동일) | C9: 경 | D9: 경 | E9: 경 | F9: 경 | G9: 경 | H9: 경 | I9: 경 | J9: 경 | K9: 중 | L9: 최 | M9: 최 | N9: 최 | O9: 중 | P9: 중 | Q9: 중 | R9: 중 | S9: 최 | T9: 최 | U9: 최 | V9: 중 | W9: 중 | X9: 중 | Y9: 경 | Z9: 경 | AA9: A1 별표3 | AB9: 확정
A10: 육지 계시별 적용 종별 — 토요일 (공휴일 아닌) | B10: 위 계시별 적용 종별에 한함. 최대부하시간대 사용량을 중간부하로 계량 → 실질 최대부하 없음. 주택용 누진제는 제외 | C10: 경 | D10: 경 | E10: 경 | F10: 경 | G10: 경 | H10: 경 | I10: 경 | J10: 경 | K10: 중 | L10: 중 | M10: 중 | N10: 중 | O10: 중 | P10: 중 | Q10: 중 | R10: 중 | S10: 중 | T10: 중 | U10: 중 | V10: 중 | W10: 중 | X10: 중 | Y10: 경 | Z10: 경 | AA10: A1 별표3 단서1 | AB10: 확정
A11: 육지 계시별 적용 종별 — 공휴일 | B11: 위 계시별 적용 종별에 한함. 전 시간대를 경부하로 계량 (임시공휴일 제외). 주택용 누진제는 제외 | C11: 경 | D11: 경 | E11: 경 | F11: 경 | G11: 경 | H11: 경 | I11: 경 | J11: 경 | K11: 경 | L11: 경 | M11: 경 | N11: 경 | O11: 경 | P11: 경 | Q11: 경 | R11: 경 | S11: 경 | T11: 경 | U11: 경 | V11: 경 | W11: 경 | X11: 경 | Y11: 경 | Z11: 경 | AA11: A1 별표3 단서1·3 | AB11: 확정
A12: 제주 계시별 적용 종별 — 전 계절, 평일 | B12: 2021.9.1~ 현행 유지. 계시별 전 종별 + 주택용 계시별 선택요금 가입자(제주는 주거용 전 가구 신청 가능). 주택용 누진제·계절별 단일요금 종별은 제외. 토요일·공휴일 계량 특례는 육지와 동일 | C12: 경 | D12: 경 | E12: 경 | F12: 경 | G12: 경 | H12: 경 | I12: 경 | J12: 경 | K12: 중 | L12: 중 | M12: 중 | N12: 중 | O12: 중 | P12: 중 | Q12: 중 | R12: 중 | S12: 최 | T12: 최 | U12: 최 | V12: 최 | W12: 최 | X12: 최 | Y12: 경 | Z12: 경 | AA12: A1 별표3 단서4 | AB12: 확정
A13: 봄·가을 토요일 주말 할인요금 — 산업용(을)·EV 충전전력만 | B13: 2026.4.16~2030.12.31, 11~14시 전력량요금 50% 할인. 대상: 산업용(을)·전기자동차 충전전력(세칙 제48조의7). 육지·제주 공통, 유예 산업용(을) 제외 | C13: - | D13: - | E13: - | F13: - | G13: - | H13: - | I13: - | J13: - | K13: - | L13: - | M13: - | N13: 중50% | O13: 중50% | P13: 중50% | Q13: - | R13: - | S13: - | T13: - | U13: - | V13: - | W13: - | X13: - | Y13: - | Z13: - | AA13: A2 제48조의7·S03 | AB13: 확정
A14: 봄·가을 일요일·공휴일 주말 할인요금 — 산업용(을)·EV 충전전력만 | B14: 2026.4.16~2030.12.31, 11~14시 전력량요금 50% 할인. 대상: 산업용(을)·전기자동차 충전전력(세칙 제48조의7). 육지·제주 공통, 유예 산업용(을) 제외 | C14: - | D14: - | E14: - | F14: - | G14: - | H14: - | I14: - | J14: - | K14: - | L14: - | M14: - | N14: 경50% | O14: 경50% | P14: 경50% | Q14: - | R14: - | S14: - | T14: - | U14: - | V14: - | W14: - | X14: - | Y14: - | Z14: - | AA14: A2 제48조의7·S03 | AB14: 확정
A16: 전부 한전 기본공급약관(2026.8.1) 별표3 원문 기준으로 확정. 읽는 법: 경=경부하(최저), 중=중간부하, 최=최대부하(최고). 핵심 3가지 — ① 개편 후 여름·봄·가을 평일은 최대부하가 15~21시로 통합, 중간부하는 08~15시와 21~22시. ② 겨울철은 개편 전과 동일(최대부하 09~12시·16~19시). ③ 제주는 개편과 무관하게 모든 계절 경부하 22~08, 중간 08~16, 최대 16~22 유지. ★ 이 표는 '지역'만으로 적용하면 안 된다. 계시별 시간대는 계시별 요금제를 적용받는 계약종별(일반용(갑)Ⅱ 선택Ⅰ·Ⅱ, 일반용(을), 산업용(갑)Ⅱ·(을), 교육용(을), EV 충전전력, 주택용 계시별 선택요금 가입자)에만 해당하며, 일반 주택용 누진제·계절별 단일요금 종별에는 시간대 개념 자체가 없다.
A17: 주말·공휴일 계량 특례(별표3 단서1): 공휴일은 최대수요전력과 사용전력량을 전 시간대 경부하로 계량하고, 공휴일이 아닌 토요일은 최대부하시간대 사용량을 중간부하로 계량한다. 여기서 '공휴일'은 관공서의 공휴일에 관한 규정상 공휴일이며 임시공휴일은 제외(단서3). 주말 할인요금(약관 제67조의7·세칙 제48조의7)은 이와 별개로 봄·가을 주말·공휴일 11~14시 전력량요금 50% 할인이며, 적용대상은 산업용(을)·전기자동차 충전전력 고객뿐이다(일반용·교육용·산업용(갑)Ⅱ·주택용 계시별은 해당 없음). 지역 제한 없음. 2030.12.31까지 효력, 3년마다 연장 검토.

Sheet 주택용
A1: 주택용 전력 — 누진제 / 주택용 계시별 선택요금 / 히트펌프 선택지
A2: 누진 단가: 2023.5.16 이후 동결(2026 3분기 기준 13분기 연속). 단가는 육지·제주 동일
A4: A. 누진제 (기본값, 전국 공통)
A5: 전압 | B5: 계절 | C5: 단계 | D5: 구간 하한(kWh) | E5: 구간 상한(kWh) | F5: 기본요금(원/호) | G5: 전력량요금(원/kWh) | H5: 근거 / 상태
A6: 저압 | B6: 기타계절(1~6, 9~12월) | C6: 1단계 | D6: 0 | E6: 200 | F6: 910 | G6: 120 | H6: A1 별표1 / 확정
A7: 저압 | B7: 기타계절(1~6, 9~12월) | C7: 2단계 | D7: 201 | E7: 400 | F7: 1600 | G7: 214.6 | H7: A1 별표1 / 확정
A8: 저압 | B8: 기타계절(1~6, 9~12월) | C8: 3단계 | D8: 401 | F8: 7300 | G8: 307.3 | H8: A1 별표1 / 확정
A9: 저압 | B9: 하계(7~8월) | C9: 1단계 | D9: 0 | E9: 300 | F9: 910 | G9: 120 | H9: A1 별표1 / 확정
A10: 저압 | B10: 하계(7~8월) | C10: 2단계 | D10: 301 | E10: 450 | F10: 1600 | G10: 214.6 | H10: A1 별표1 / 확정
A11: 저압 | B11: 하계(7~8월) | C11: 3단계 | D11: 451 | F11: 7300 | G11: 307.3 | H11: A1 별표1 / 확정
A12: 저압 | B12: 하계·동계(12~2월) | C12: 슈퍼유저 | D12: 1001 | G12: 736.2 | H12: A1 별표1 / 확정
A13: 고압 | B13: 기타계절(1~6, 9~12월) | C13: 1단계 | D13: 0 | E13: 200 | F13: 730 | G13: 105 | H13: A1 별표1 / 확정
A14: 고압 | B14: 기타계절(1~6, 9~12월) | C14: 2단계 | D14: 201 | E14: 400 | F14: 1260 | G14: 174 | H14: A1 별표1 / 확정
A15: 고압 | B15: 기타계절(1~6, 9~12월) | C15: 3단계 | D15: 401 | F15: 6060 | G15: 242.3 | H15: A1 별표1 / 확정
A16: 고압 | B16: 하계(7~8월) | C16: 1단계 | D16: 0 | E16: 300 | F16: 730 | G16: 105 | H16: A1 별표1 / 확정
A17: 고압 | B17: 하계(7~8월) | C17: 2단계 | D17: 301 | E17: 450 | F17: 1260 | G17: 174 | H17: A1 별표1 / 확정
A18: 고압 | B18: 하계(7~8월) | C18: 3단계 | D18: 451 | F18: 6060 | G18: 242.3 | H18: A1 별표1 / 확정
A19: 고압 | B19: 하계·동계(12~2월) | C19: 슈퍼유저 | D19: 1001 | G19: 601.3 | H19: A1 별표1 / 확정
A20: 누진 계산 원칙: 구간별로 해당 구간 사용량에만 그 단가를 적용(초과분 누진), 기본요금은 최종 도달 구간 1개만 부과. 저압=일반 단독·다가구 등, 고압=아파트 등 고압 수전 주택. 월간 최저요금 1,000원(A1 별표1 1-가-(3)). 슈퍼유저는 여름철 7.1~8.31과 겨울철 12.1~익년 2월 말일에만 적용. 사용전력량이 없는 월에는 기본요금 50% 감액(단, 최저요금 적용 주택용은 제외 — A1 제67조 제6항 제1호).
A22: A-1. 누진 요금 계산 예시 (저압, 수식 연동 — 파란 셀 사용량만 바꿔 보세요)
A23: 항목 | B23: 예시1 기타계절 | C23: 예시2 하계 | D23: 예시3 기타계절 | H23: 비고
A24: 월 사용량(kWh) | B24: 350 | C24: 350 | D24: 500 | H24: 입력값(파란 글씨)
A25: 1단계 상한(kWh) | B25: =E6 | C25: =E9 | D25: =E6
A26: 2단계 상한(kWh) | B26: =E7 | C26: =E10 | D26: =E7
A27: 1단계 사용량 | B27: =MIN(B24,B25) | C27: =MIN(C24,C25) | D27: =MIN(D24,D25)
A28: 2단계 사용량 | B28: =MIN(MAX(B24-B25,0),B26-B25) | C28: =MIN(MAX(C24-C25,0),C26-C25) | D28: =MIN(MAX(D24-D25,0),D26-D25)
A29: 3단계 사용량 | B29: =MAX(B24-B26,0) | C29: =MAX(C24-C26,0) | D29: =MAX(D24-D26,0)
A30: 기본요금 | B30: =IF(B24<=B25,F6,IF(B24<=B26,F7,F8)) | C30: =IF(C24<=C25,F9,IF(C24<=C26,F10,F11)) | D30: =IF(D24<=D25,F6,IF(D24<=D26,F7,F8))
A31: 전력량요금 | B31: =B27*G6+B28*G7+B29*G8 | C31: =C27*G9+C28*G10+C29*G11 | D31: =D27*G6+D28*G7+D29*G8
A32: 기후환경요금 | B32: =B24*요금구성_공통!$C$5 | C32: =C24*요금구성_공통!$C$5 | D32: =D24*요금구성_공통!$C$5
A33: 연료비조정요금 | B33: =B24*요금구성_공통!$C$6 | C33: =C24*요금구성_공통!$C$6 | D33: =D24*요금구성_공통!$C$6
A34: 전기요금 계(①) | B34: =SUM(B30:B33) | C34: =SUM(C30:C33) | D34: =SUM(D30:D33)
A35: 부가가치세(①×10%) | B35: =B34*요금구성_공통!$C$7 | C35: =C34*요금구성_공통!$C$7 | D35: =D34*요금구성_공통!$C$7
A36: 전력산업기반기금(①×2.7%) | B36: =B34*요금구성_공통!$C$8 | C36: =C34*요금구성_공통!$C$8 | D36: =D34*요금구성_공통!$C$8
A37: 청구 추정액 | B37: =B34+B35+B36 | C37: =C34+C35+C36 | D37: =D34+D35+D36 | H37: 원단위 절사·복지할인 미반영 근사치
A38: 예시1 vs 예시2: 같은 350kWh라도 하계(7~8월)는 1단계가 300kWh까지 확대되어 요금이 낮다. 예시3: 400kWh를 넘는 순간 기본요금이 1,600→7,300원으로 뛰고 초과분에 307.3원이 적용된다 → HEMS의 월말 누적량 관리 근거.
A40: B. 주택용 계절·시간대별(계시별) 선택요금 — 제주 주거용 전 가구(2021.9.1~) / 육지 인증 지열·공기열 설치 가구(2026.4.1~) · 세칙 제48조의5·별표12
A41: 구분 | B41: 기본요금 (세칙 별표12) | C41: 시간대 | D41: 여름·겨울 (원/kWh) | E41: 봄·가을 (원/kWh) | F41: 제주 시간대 | G41: 육지 시간대 | H41: 근거 / 상태
A42: 주택용 계시별 | B42: 4,310원/kW × 요금적용전력 3kW/가구 | C42: 경부하 | D42: 138.7 | E42: 125.8 | F42: 22~08시 | G42: 22~08시 | H42: A2 별표12 / 확정
A43: 주택용 계시별 | B43: =월 12,930원/가구 (저압·고압 동일) | C43: 중간부하 | D43: 184.7 | E43: 153.8 | F43: 08~16시 | G43: 08~15, 21~22시 | H43: A2 별표12 / 확정
...

Sheet 요금구성_공통
A1: 전기요금 공통 부과 항목 (2026년 9월 기준)
A2: C열 값은 '주택용' 계산 예시가 참조하는 입력 셀
A4: 항목 | B4: 단위 | C4: 값 | D4: 적용 기준 | E4: 근거 / 상태
A5: 기후환경요금 | B5: 원/kWh | C5: 9 | D5: 전 사용량에 부과. RPS+ETS+석탄발전 감축비용+에너지캐시백 지원금 (2023.1.1~ 9.0원) | E5: A1 별표7 부칙 / 확정
A6: 연료비조정요금 | B6: 원/kWh | C6: 5 | D6: 2026년 3분기 +5원. 약관상 상하한 ±5원/kWh (분기별 결정) | E6: A1 별표8·S07 / 확정
A7: 부가가치세 | B7: 비율 | C7: 0.1 | D7: 전기요금 계 × 10% | E7: 법정 / 확정
A8: 전력산업기반기금 | B8: 비율 | C8: 0.027 | D8: 전기요금 계 × 2.7% (2025.7~). 약관 제82조에 따라 전기요금과 병기청구 | E8: A1 제82조·S09 / 확정
A10: 청구 구조(A1 제67조 제1항): 전기요금 = 기본요금 + 전력량요금 + 기후환경요금 ± 연료비조정요금. 여기에 부가세 10%와 전력산업기반기금 2.7%가 병기청구된다. 끝수 처리(A1 제7조): 청구금액의 10원 미만 끝수는 계산하지 않는다. 연료비조정단가는 실적연료비와 기준연료비 차이에 변환계수를 곱해 산정하되 ±5원/kWh를 넘지 못한다(별표8).

Sheet 일반용
A1: 일반용 전력 (갑Ⅰ / 갑Ⅱ / 을 / 보완전력)
A2: 단가: 2025.04.01 시행 요금표(S05). 2026.6.1부터 갑Ⅱ·을은 시간대 구분만 개편(단가 조정 없음, 평균 1원 미만 하락 — S02)
A4: 종별 | B4: 전압 | C4: 선택 | D4: 기본요금(원/kW) | E4: 시간대 | F4: 여름(6~8월) | G4: 봄·가을(3~5,9~10월) | H4: 겨울(11~2월) | I4: 근거 / 상태
A5: 일반용(갑)Ⅰ — 계약전력 300kW 미만, 계절별 단일요금
A6: 일반용(갑)Ⅰ | B6: 저압 | C6: - | D6: 6160 | E6: 계절별 단일 | F6: 132.4 | G6: 91.9 | H6: 119 | I6: S05 / 확정
A7: 일반용(갑)Ⅰ | B7: 고압A | C7: Ⅰ | D7: 7170 | E7: 계절별 단일 | F7: 142.6 | G7: 98.6 | H7: 130.3 | I7: S05 / 확정
A8: 일반용(갑)Ⅰ | B8: 고압A | C8: Ⅱ | D8: 8230 | E8: 계절별 단일 | F8: 138.6 | G8: 94.3 | H8: 125 | I8: S05 / 확정
A9: 일반용(갑)Ⅰ | B9: 고압B | C9: Ⅰ | D9: 7170 | E9: 계절별 단일 | F9: 140.5 | G9: 97.5 | H9: 127.3 | I9: S05 / 확정
A10: 일반용(갑)Ⅰ | B10: 고압B | C10: Ⅱ | D10: 8230 | E10: 계절별 단일 | F10: 135.2 | G10: 92.2 | H10: 122 | I10: S05 / 확정
A11: 일반용(갑)Ⅱ — 계약전력 300kW 미만, 시간대별 계량기 설치(계시별). 2026.6.1~ 개편 시간대 적용
A12: 일반용(갑)Ⅱ | B12: 고압A | C12: Ⅰ | D12: 7170 | E12: 경부하 | F12: 89.4 | G12: 89.4 | H12: 98.1 | I12: S05 / 확정
A13: 일반용(갑)Ⅱ | B13: 고압A | C13: Ⅰ | D13: 7170 | E13: 중간부하 | F13: 140.6 | G13: 96.8 | H13: 128.5 | I13: S05 / 확정
A14: 일반용(갑)Ⅱ | B14: 고압A | C14: Ⅰ | D14: 7170 | E14: 최대부하 | F14: 163.1 | G14: 108.1 | H14: 143.3 | I14: S05 / 확정
A15: 일반용(갑)Ⅱ | B15: 고압A | C15: Ⅱ | D15: 8230 | E15: 경부하 | F15: 84.1 | G15: 84.1 | H15: 92.8 | I15: S05 / 확정
A16: 일반용(갑)Ⅱ | B16: 고압A | C16: Ⅱ | D16: 8230 | E16: 중간부하 | F16: 135.3 | G16: 91.5 | H16: 123.2 | I16: S05 / 확정
A17: 일반용(갑)Ⅱ | B17: 고압A | C17: Ⅱ | D17: 8230 | E17: 최대부하 | F17: 157.8 | G17: 102.8 | H17: 138 | I17: S05 / 확정
A18: 일반용(갑)Ⅱ | B18: 고압B | C18: Ⅰ | D18: 7170 | E18: 경부하 | F18: 88.8 | G18: 88.8 | H18: 97.8 | I18: S05 / 확정
A19: 일반용(갑)Ⅱ | B19: 고압B | C19: Ⅰ | D19: 7170 | E19: 중간부하 | F19: 137.4 | G19: 94.7 | H19: 125.1 | I19: S05 / 확정
A20: 일반용(갑)Ⅱ | B20: 고압B | C20: Ⅰ | D20: 7170 | E20: 최대부하 | F20: 153.8 | G20: 100.1 | H20: 139.3 | I20: S05 / 확정
A21: 일반용(갑)Ⅱ | B21: 고압B | C21: Ⅱ | D21: 8230 | E21: 경부하 | F21: 83.5 | G21: 83.5 | H21: 92.5 | I21: S05 / 확정
A22: 일반용(갑)Ⅱ | B22: 고압B | C22: Ⅱ | D22: 8230 | E22: 중간부하 | F22: 132.1 | G22: 89.4 | H22: 119.8 | I22: S05 / 확정
A23: 일반용(갑)Ⅱ | B23: 고압B | C23: Ⅱ | D23: 8230 | E23: 최대부하 | F23: 148.5 | G23: 94.8 | H23: 134 | I23: S05 / 확정
A24: 일반용(갑)Ⅱ 선택(Ⅲ)·(Ⅳ) — 2026.6.1 신설, 계시별이 아닌 계절별 단일요금 (A1 별표1·부칙 2026.5.22)
A25: 일반용(갑)Ⅱ | B25: 고압A | C25: Ⅲ | D25: 7170 | E25: 계절별 단일 | F25: 142.6 | G25: 98.6 | H25: 130.3 | I25: A1 별표1 / 확정
A26: 일반용(갑)Ⅱ | B26: 고압A | C26: Ⅳ | D26: 8230 | E26: 계절별 단일 | F26: 138.6 | G26: 94.3 | H26: 125 | I26: A1 별표1 / 확정
A27: 일반용(갑)Ⅱ | B27: 고압B | C27: Ⅲ | D27: 7170 | E27: 계절별 단일 | F27: 140.5 | G27: 97.5 | H27: 127.3 | I27: A1 별표1 / 확정
A28: 일반용(갑)Ⅱ | B28: 고압B | C28: Ⅳ | D28: 8230 | E28: 계절별 단일 | F28: 135.2 | G28: 92.2 | H28: 122 | I28: A1 별표1 / 확정
A29: 선택Ⅲ·Ⅳ는 시간대 이동이 어려운 고객을 위한 계절별 단일요금(갑Ⅰ과 동일 단가). 2026년 6~11월분은 기존 선택Ⅰ↔Ⅲ, 선택Ⅱ↔Ⅳ를 비교해 낮은 요금을 자동 적용하고, 고객이 신청한 선택Ⅲ·Ⅳ는 2026년 12월분부터 적용(A1 부칙 2026.5.22).
A30: 일반용(을) — 계약전력 300kW 이상, 계시별 필수. 2026.6.1~ 개편 시간대 적용
A31: 일반용(을) | B31: 고압A | C31: Ⅰ | D31: 7220 | E31: 경부하 | F31: 92.8 | G31: 92.8 | H31: 99.8 | I31: S05 / 확정
A32: 일반용(을) | B32: 고압A | C32: Ⅰ | D32: 7220 | E32: 중간부하 | F32: 145.7 | G32: 115.3 | H32: 145.9 | I32: S05 / 확정
A33: 일반용(을) | B33: 고압A | C33: Ⅰ | D33: 7220 | E33: 최대부하 | F33: 227.8 | G33: 146 | H33: 203.4 | I33: S05 / 확정
A34: 일반용(을) | B34: 고압A | C34: Ⅱ | D34: 8320 | E34: 경부하 | F34: 87.3 | G34: 87.3 | H34: 94.3 | I34: S05 / 확정
A35: 일반용(을) | B35: 고압A | C35: Ⅱ | D35: 8320 | E35: 중간부하 | F35: 140.2 | G35: 109.8 | H35: 140.4 | I35: S05 / 확정
A36: 일반용(을) | B36: 고압A | C36: Ⅱ | D36: 8320 | E36: 최대부하 | F36: 222.3 | G36: 140.5 | H36: 197.9 | I36: S05 / 확정
A37: 일반용(을) | B37: 고압A | C37: Ⅲ | D37: 9810 | E37: 경부하 | F37: 86.4 | G37: 86.4 | H37: 93.7 | I37: S05 / 확정
A38: 일반용(을) | B38: 고압A | C38: Ⅲ | D38: 9810 | E38: 중간부하 | F38: 139.6 | G38: 108.5 | H38: 139.8 | I38: S05 / 확정
A39: 일반용(을) | B39: 고압A | C39: Ⅲ | D39: 9810 | E39: 최대부하 | F39: 209.9 | G39: 132.2 | H39: 186.7 | I39: S05 / 확정
A40: 일반용(을) | B40: 고압B | C40: Ⅰ | D40: 6630 | E40: 경부하 | F40: 95.9 | G40: 95.9 | H40: 102.9 | I40: S05 / 확정
A41: 일반용(을) | B41: 고압B | C41: Ⅰ | D41: 6630 | E41: 중간부하 | F41: 148.2 | G41: 118.2 | H41: 148.2 | I41: S05 / 확정
...

Sheet 산업용
A1: 산업용 전력 (갑Ⅰ / 갑Ⅱ / 을) — 약관 별표1(2026.6.1 적용) 기준
A2: 산업용(을) 단가는 2026.4.16 개편이 반영된 현행 단가. 오른쪽 3개 열은 유예 신청 고객(~2026.9.30)에게 적용되는 환산 단가(부칙 2026.3.16 제4호 계산식)
A4: 유예 고객 환산 조정폭 (산업용(을) 중 유예 신청분, ~2026.9.30, A1 부칙 2026.3.16 제4호)
A5: 항목 | B5: 조정폭(원/kWh) | C5: 비고
A6: 경부하 | B6: -5.1 | C6: 차감
A7: 중간부하 | B7: 0 | C7: 조정 없음
A8: 최대부하 여름·겨울 | B8: 16.9 | C8: 가산
A9: 최대부하 봄·가을 | B9: 13.2 | C9: 가산
A11: 종별 | B11: 전압 | C11: 선택 | D11: 기본요금(원/kW) | E11: 시간대 | F11: 여름(6~8월) | G11: 봄·가을(3~5,9~10월) | H11: 겨울(11~2월) | I11: 유예고객 여름 | J11: 유예고객 봄·가을 | K11: 유예고객 겨울 | L11: 근거 / 상태
A12: 산업용(갑)Ⅰ — 계약전력 300kW 미만, 계절별 단일요금 (2024.10.24 +8.5원 반영)
A13: 산업용(갑)Ⅰ | B13: 저압 | C13: - | D13: 5550 | E13: 계절별 단일 | F13: 116.2 | G13: 94.4 | H13: 114.5 | I13: 해당없음 | L13: S05 / 확정
A14: 산업용(갑)Ⅰ | B14: 고압A | C14: Ⅰ | D14: 6490 | E14: 계절별 단일 | F14: 124.8 | G14: 101.1 | H14: 124.7 | I14: 해당없음 | L14: S05 / 확정
A15: 산업용(갑)Ⅰ | B15: 고압A | C15: Ⅱ | D15: 7470 | E15: 계절별 단일 | F15: 120 | G15: 96.5 | H15: 118.2 | I15: 해당없음 | L15: S05 / 확정
A16: 산업용(갑)Ⅰ | B16: 고압B | C16: Ⅰ | D16: 6000 | E16: 계절별 단일 | F16: 123.6 | G16: 100 | H16: 123.2 | I16: 해당없음 | L16: S05 / 확정
A17: 산업용(갑)Ⅰ | B17: 고압B | C17: Ⅱ | D17: 6900 | E17: 계절별 단일 | F17: 118.9 | G17: 95.4 | H17: 117.1 | I17: 해당없음 | L17: S05 / 확정
A18: 산업용(갑)Ⅱ — 계약전력 300kW 미만, 계시별. 2026.6.1~ 개편 시간대 적용 (단가 조정 여부 보도자료상 불명확 → 추정 미산출)
A19: 산업용(갑)Ⅱ | B19: 고압A | C19: Ⅰ | D19: 6490 | E19: 경부하 | F19: 95.7 | G19: 95.7 | H19: 103.1 | I19: 확인필요 | L19: S05 / 기준단가 확정
A20: 산업용(갑)Ⅱ | B20: 고압A | C20: Ⅰ | D20: 6490 | E20: 중간부하 | F20: 121.5 | G20: 100.5 | H20: 120 | I20: 확인필요 | L20: S05 / 기준단가 확정
A21: 산업용(갑)Ⅱ | B21: 고압A | C21: Ⅰ | D21: 6490 | E21: 최대부하 | F21: 155 | G21: 119.7 | H21: 149.4 | I21: 확인필요 | L21: S05 / 기준단가 확정
A22: 산업용(갑)Ⅱ | B22: 고압A | C22: Ⅱ | D22: 7470 | E22: 경부하 | F22: 90.8 | G22: 90.8 | H22: 98.2 | I22: 확인필요 | L22: S05 / 기준단가 확정
A23: 산업용(갑)Ⅱ | B23: 고압A | C23: Ⅱ | D23: 7470 | E23: 중간부하 | F23: 116.6 | G23: 95.6 | H23: 115.1 | I23: 확인필요 | L23: S05 / 기준단가 확정
A24: 산업용(갑)Ⅱ | B24: 고압A | C24: Ⅱ | D24: 7470 | E24: 최대부하 | F24: 150.1 | G24: 114.8 | H24: 144.5 | I24: 확인필요 | L24: S05 / 기준단가 확정
A25: 산업용(갑)Ⅱ | B25: 고압B | C25: Ⅰ | D25: 6000 | E25: 경부하 | F25: 92.5 | G25: 92.5 | H25: 99.7 | I25: 확인필요 | L25: S05 / 기준단가 확정
A26: 산업용(갑)Ⅱ | B26: 고압B | C26: Ⅰ | D26: 6000 | E26: 중간부하 | F26: 120.1 | G26: 99.1 | H26: 117.7 | I26: 확인필요 | L26: S05 / 기준단가 확정
A27: 산업용(갑)Ⅱ | B27: 고압B | C27: Ⅰ | D27: 6000 | E27: 최대부하 | F27: 153.9 | G27: 117.9 | H27: 146.4 | I27: 확인필요 | L27: S05 / 기준단가 확정
A28: 산업용(갑)Ⅱ | B28: 고압B | C28: Ⅱ | D28: 6900 | E28: 경부하 | F28: 88 | G28: 88 | H28: 95.2 | I28: 확인필요 | L28: S05 / 기준단가 확정
A29: 산업용(갑)Ⅱ | B29: 고압B | C29: Ⅱ | D29: 6900 | E29: 중간부하 | F29: 115.6 | G29: 94.6 | H29: 113.2 | I29: 확인필요 | L29: S05 / 기준단가 확정
A30: 산업용(갑)Ⅱ | B30: 고압B | C30: Ⅱ | D30: 6900 | E30: 최대부하 | F30: 149.4 | G30: 113.4 | H30: 141.9 | I30: 확인필요 | L30: S05 / 기준단가 확정
A31: 산업용(을) — 계약전력 300kW 이상, 계시별 필수. 아래 단가는 2026.4.16 개편이 반영된 현행 단가(A1 별표1, 2026.6.1 적용)
A32: 산업용(을) | B32: 고압A | C32: Ⅰ | D32: 7220 | E32: 경부하 | F32: 121.5 | G32: 121.5 | H32: 128.5 | I32: =F32+$B$6 | J32: =G32+$B$6 | K32: =H32+$B$6 | L32: A1 별표1 / 확정
A33: 산업용(을) | B33: 고압A | C33: Ⅰ | D33: 7220 | E33: 중간부하 | F33: 169.3 | G33: 138.9 | H33: 169.5 | I33: =F33+$B$7 | J33: =G33+$B$7 | K33: =H33+$B$7 | L33: A1 별표1 / 확정
A34: 산업용(을) | B34: 고압A | C34: Ⅰ | D34: 7220 | E34: 최대부하 | F34: 234.5 | G34: 156.4 | H34: 210.1 | I34: =F34+$B$8 | J34: =G34+$B$9 | K34: =H34+$B$8 | L34: A1 별표1 / 확정
A35: 산업용(을) | B35: 고압A | C35: Ⅱ | D35: 8320 | E35: 경부하 | F35: 116 | G35: 116 | H35: 123 | I35: =F35+$B$6 | J35: =G35+$B$6 | K35: =H35+$B$6 | L35: A1 별표1 / 확정
A36: 산업용(을) | B36: 고압A | C36: Ⅱ | D36: 8320 | E36: 중간부하 | F36: 163.8 | G36: 133.4 | H36: 164 | I36: =F36+$B$7 | J36: =G36+$B$7 | K36: =H36+$B$7 | L36: A1 별표1 / 확정
A37: 산업용(을) | B37: 고압A | C37: Ⅱ | D37: 8320 | E37: 최대부하 | F37: 229 | G37: 150.9 | H37: 204.6 | I37: =F37+$B$8 | J37: =G37+$B$9 | K37: =H37+$B$8 | L37: A1 별표1 / 확정
A38: 산업용(을) | B38: 고압A | C38: Ⅲ | D38: 9810 | E38: 경부하 | F38: 115.1 | G38: 115.1 | H38: 122.4 | I38: =F38+$B$6 | J38: =G38+$B$6 | K38: =H38+$B$6 | L38: A1 별표1 / 확정
A39: 산업용(을) | B39: 고압A | C39: Ⅲ | D39: 9810 | E39: 중간부하 | F39: 163.2 | G39: 132.1 | H39: 163.4 | I39: =F39+$B$7 | J39: =G39+$B$7 | K39: =H39+$B$7 | L39: A1 별표1 / 확정
A40: 산업용(을) | B40: 고압A | C40: Ⅲ | D40: 9810 | E40: 최대부하 | F40: 216.6 | G40: 142.6 | H40: 193.4 | I40: =F40+$B$8 | J40: =G40+$B$9 | K40: =H40+$B$8 | L40: A1 별표1 / 확정
A41: 산업용(을) | B41: 고압B | C41: Ⅰ | D41: 6630 | E41: 경부하 | F41: 131.4 | G41: 131.4 | H41: 138.4 | I41: =F41+$B$6 | J41: =G41+$B$6 | K41: =H41+$B$6 | L41: A1 별표1 / 확정
A42: 산업용(을) | B42: 고압B | C42: Ⅰ | D42: 6630 | E42: 중간부하 | F42: 178.6 | G42: 148.6 | H42: 178.6 | I42: =F42+$B$7 | J42: =G42+$B$7 | K42: =H42+$B$7 | L42: A1 별표1 / 확정
...

Sheet 교육용
A1: 교육용 전력 (갑 / 을)
A2: 단가: 2025.04.01 요금표(S05). 교육용(을)은 2026.6.1~ 개편 시간대 적용(단가 조정 없음 — S02)
A4: 종별 | B4: 전압 | C4: 선택 | D4: 기본요금(원/kW) | E4: 시간대 | F4: 여름(6~8월) | G4: 봄·가을(3~5,9~10월) | H4: 겨울(11~2월) | I4: 근거 / 상태
A5: 교육용(갑) — 계약전력 1,000kW 미만, 계절별 단일요금
A6: 교육용(갑) | B6: 저압 | C6: - | D6: 5230 | E6: 계절별 단일 | F6: 123.6 | G6: 86.4 | H6: 110.8 | I6: S05 / 확정
A7: 교육용(갑) | B7: 고압A | C7: Ⅰ | D7: 5550 | E7: 계절별 단일 | F7: 123.3 | G7: 86.5 | H7: 109.3 | I7: S05 / 확정
A8: 교육용(갑) | B8: 고압A | C8: Ⅱ | D8: 6370 | E8: 계절별 단일 | F8: 118.8 | G8: 82.1 | H8: 104.8 | I8: S05 / 확정
A9: 교육용(갑) | B9: 고압B | C9: Ⅰ | D9: 5550 | E9: 계절별 단일 | F9: 122.6 | G9: 86.1 | H9: 108.5 | I9: S05 / 확정
A10: 교육용(갑) | B10: 고압B | C10: Ⅱ | D10: 6370 | E10: 계절별 단일 | F10: 118.1 | G10: 81.6 | H10: 104 | I10: S05 / 확정
A11: 교육용(을) — 계약전력 1,000kW 이상, 계시별
A12: 교육용(을) | B12: 고압A | C12: Ⅰ | D12: 6090 | E12: 경부하 | F12: 76.5 | G12: 76.5 | H12: 80.5 | I12: S05 / 확정
A13: 교육용(을) | B13: 고압A | C13: Ⅰ | D13: 6090 | E13: 중간부하 | F13: 121.2 | G13: 90.9 | H13: 119.7 | I13: S05 / 확정
A14: 교육용(을) | B14: 고압A | C14: Ⅰ | D14: 6090 | E14: 최대부하 | F14: 187.1 | G14: 111.4 | H14: 158.4 | I14: S05 / 확정
A15: 교육용(을) | B15: 고압A | C15: Ⅱ | D15: 6980 | E15: 경부하 | F15: 72 | G15: 72 | H15: 76 | I15: S05 / 확정
A16: 교육용(을) | B16: 고압A | C16: Ⅱ | D16: 6980 | E16: 중간부하 | F16: 116.7 | G16: 86.4 | H16: 115.2 | I16: S05 / 확정
A17: 교육용(을) | B17: 고압A | C17: Ⅱ | D17: 6980 | E17: 최대부하 | F17: 182.6 | G17: 106.9 | H17: 153.9 | I17: S05 / 확정
A18: 교육용(을) | B18: 고압B | C18: Ⅰ | D18: 6090 | E18: 경부하 | F18: 75 | G18: 75 | H18: 78.8 | I18: S05 / 확정
A19: 교육용(을) | B19: 고압B | C19: Ⅰ | D19: 6090 | E19: 중간부하 | F19: 118.5 | G19: 89.2 | H19: 116.8 | I19: S05 / 확정
A20: 교육용(을) | B20: 고압B | C20: Ⅰ | D20: 6090 | E20: 최대부하 | F20: 181.4 | G20: 109 | H20: 154.1 | I20: S05 / 확정
A21: 교육용(을) | B21: 고압B | C21: Ⅱ | D21: 6980 | E21: 경부하 | F21: 70.5 | G21: 70.5 | H21: 74.3 | I21: S05 / 확정
A22: 교육용(을) | B22: 고압B | C22: Ⅱ | D22: 6980 | E22: 중간부하 | F22: 114 | G22: 84.7 | H22: 112.3 | I22: S05 / 확정
A23: 교육용(을) | B23: 고압B | C23: Ⅱ | D23: 6980 | E23: 최대부하 | F23: 176.9 | G23: 104.5 | H23: 149.6 | I23: S05 / 확정

Sheet 농사용_가로등_심야
A1: 농사용 / 가로등 / 심야전력
A2: 단가: 2025.04.01 요금표(S05)
A4: 종별 | B4: 구분 | C4: 기본요금 | D4: 여름(6~8월) | E4: 봄·가을(3~5,9~10월) | F4: 겨울(11~2월) | G4: 비고 | H4: 근거 / 상태
A5: 농사용 | B5: 갑 | C5: 360원/kW | D5: 48.3 | E5: 48.3 | F5: 48.3 | G5: 양수·양배수 등. 요금표상 계절 구분 없음 | H5: A1 별표1 / 확정
A6: 농사용 | B6: 을(저압) | C6: 1,150원/kW | D6: 65.9 | E6: 65.9 | F6: 65.9 | G6: 요금표상 계절 구분 없음 | H6: A1 별표1 / 확정
A7: 농사용 | B7: 을(고압A·B) | C7: 1,210원/kW | D7: 68.6 | E7: 66.6 | F7: 68.6 | H7: A1 별표1 / 확정
A8: 가로등 | B8: 갑(정액등) | C8: W당 47.2원 | G8: 월 최저요금 1,220원 | H8: A1 별표1 / 확정
A9: 가로등 | B9: 을(종량등) | C9: 6,290원/kW | D9: 112.6 | E9: 112.6 | F9: 112.6 | H9: A1 별표1 / 확정
A10: 심야전력 | B10: 갑 | C10: 없음 | D10: 82.1 | E10: 82.1 | F10: 103.5 | G10: 심야(22~08시) 전용. 기타계절 82.1 / 겨울 103.5 | H10: S05 / 확인필요(선택공급약관 소관)
A11: 심야전력 | B11: 을 | C11: 없음 | D11: 71.9 | E11: 71.9 | F11: 89 | G11: 기타계절 71.9 / 겨울 89.0 | H11: S05 / 확인필요(선택공급약관 소관)
A12: 심야전력 | B12: 을Ⅱ | C12: 7,160원/kW | D12: 71.9 | E12: 71.9 | F12: 89 | G12: 심야시간 단가. 기타시간 115.1원/kWh, 월 최저 kW당 710원 | H12: S05 / 확인필요(선택공급약관 소관)
A13: 농사용·가로등 단가는 약관 별표1(2026.6.1 적용)로 확정. 심야전력은 약관 별표1에 항목이 없고, 2026.8.1판 시행세칙(232쪽)에도 단가표가 없다(언급만 있음) → 소관은 선택공급약관이며 신규 가입이 중단된 경과 요금제. 표의 심야전력 값은 2025.04 요금표 전재자료 기준이며 현행 여부 확인 필요. 참고로 약관 별표1에는 임시전력이 추가로 있으며, 임시전력(갑)은 주택용 요금, 임시전력(을)은 계약전력에 따라 일반용(갑)Ⅰ·Ⅱ 또는 일반용(을) 요금을 적용한다.

Sheet 전기차충전
A1: 전기자동차 충전전력요금 (별도 계약종별)
A2: 정정: 이전 버전의 '별도 종별 없음'은 오류. 한전 '전기자동차 충전전력요금'이 별도 존재하며, 2022.7 폐지된 것은 '특례할인'이다(S21·S22)
A4: 구분 | B4: 기본요금(원/kW) | C4: 시간대 | D4: 여름(6~8월) | E4: 봄·가을(3~5,9~10월) | F4: 겨울(11~2월) | G4: 근거 / 상태
A5: 저압 (단독·빌라 등) | B5: 2390 | C5: 경부하 | D5: 84.3 | E5: 85.4 | F5: 107.4 | G5: A2 별표4 제4호 / 확정
A6: 저압 (단독·빌라 등) | B6: 2390 | C6: 중간부하 | D6: 172 | E6: 97.2 | F6: 154.9 | G6: A2 별표4 제4호 / 확정
A7: 저압 (단독·빌라 등) | B7: 2390 | C7: 최대부하 | D7: 259.2 | E7: 102.1 | F7: 217.5 | G7: A2 별표4 제4호 / 확정
A8: 고압 (아파트 등) | B8: 2580 | C8: 경부하 | D8: 79.2 | E8: 80.2 | F8: 96.6 | G8: A2 별표4 제4호 / 확정
A9: 고압 (아파트 등) | B9: 2580 | C9: 중간부하 | D9: 137.4 | E9: 91 | F9: 127.7 | G9: A2 별표4 제4호 / 확정
A10: 고압 (아파트 등) | B10: 2580 | C10: 최대부하 | D10: 190.4 | E10: 94.9 | F10: 165.5 | G10: A2 별표4 제4호 / 확정
A11: 확정: 위 저압·고압(자가소비용) 단가는 세칙 별표4 제4호 전기자동차 충전전력 요금표(PDF 161쪽) 원문과 전량 일치. 교차검증: 2026.4 정부 발표의 EV 할인액(토 48.6원, 일·공휴일 42.7원)도 저압 봄·가을 중간부하 97.2원·경부하 85.4원의 정확히 50%와 일치(S03). 세칙에는 이 외에 충전사업자용 선택(Ⅰ)~(Ⅳ) 요금표가 별도로 있다(자가소비 고객은 선택 불가).
A13: 2026년 변경 사항
A14: 항목 | B14: 내용 | G14: 근거
A15: 약관상 근거 | B15: 약관 제18조의3(전기자동차 충전용설비에 대한 전기사용계약기준)이 별도 조문으로 존재하고, 부칙 2026.3.16 제8호도 '전기자동차 충전전력'을 별도 종별로 다룬다. 단가표는 별표1이 아니라 세칙 별표4 제4호 '전기자동차 충전전력 요금표'에 있음(자가소비용 저압/고압 + 충전사업자 선택Ⅰ~Ⅳ) | G15: A2 별표4 제4호·S03·S04·S22 / 확정
A16: 시간대 개편 | B16: 2026.4.16~ 계시별 개편 시간대 적용 (평일 최대부하 15~21시). 원격검침 불가 고객은 가능 시점에 소급 반영(부칙 제8호) | G16: S03·S04·S22 / 확정
A17: 봄·가을 주말·공휴일 할인 | B17: 2026.4.18~ 11~14시 전력량요금 50% (자가소비용 충전소 약 9.4만곳, 공공 급속충전기 약 1.3만기). 로밍요금은 제외. 세칙 제48조의7: 산업용(을)·EV 충전전력만 대상, 지역 제한 없음 | G17: A2 제48조의7·S03·S04·S22 / 확정
A18: 할인액 | B18: 토요일 kWh당 48.6원, 일요일·공휴일 42.7원 (자가소비용 40.1~48.6원) | G18: S03·S04·S22 / 확정
A19: 특례할인 연혁 | B19: 2017~2021 기본요금·전력량요금 특례할인 → 단계 축소 → 2022.7 완전 폐지 | G19: S03·S04·S22 / 확정

Sheet DR_수요반응
A1: 수요반응(DR) 제도 정리 — 육지·제주, 가정 HEMS 관점
A2: 근거: 전력시장운영규칙 제12장 수요반응자원의 거래(2026.7.24판, 출처 S35) · 별표26 정산기준 · 별표28 고객기준부하 · 전력거래소 「2025년 12월 수요자원거래시장 현황 및 운영정보」(2026.3 발간, S33) · 전력거래소 2026 사업실명제 내역서(S32) · 한전 선택공급약관 제3장 긴급절전 수요조정(S34). 셀 색상: 흰색=원문 확정 / 노랑=추정·산출 / 주황=확인필요. 핵심: DR 시장은 한전이 아니라 전력거래소(KPX)가 운영하고, 가정은 전력거래소와 직접 거래·정산할 수 없고(전력거래자 등록은 수요관리사업자만 가능, 제12.1.3조·제12.2.1조) 반드시 수요관리사업자(앱)의 고객으로 참여한다. 한전 자체 제도는 긴급절전(대형 사업장)과 에너지캐시백(주택, DR 아님)뿐이다.
A4: A. 한눈에 보기 — 누가 운영하고, 가정은 어디에 해당하나
A5: 구분 | B5: 운영 주체 | C5: 가정(주택용)이 해당하는 제도 | D5: 참여 경로 | E5: 보상 형태 | F5: 2026.2 참여 규모 | G5: 근거 | H5: 상태
A6: 전력거래소 수요자원거래시장 | B6: 전력거래소(KPX). 수요관리사업자가 자원을 등록하고 고객을 모집 | C6: 국민DR(감축), 플러스DR(증대). 둘은 중복 등록 가능 | D6: 수요관리사업자와 계약 → 사업자 앱/알림으로 발령 수신 → 실적은 AMI 계량으로 자동 산정 | E6: KPX → 사업자에게 정산금(원/kWh) 지급 → 사업자가 계약에 따라 고객에게 현금·포인트·기부 등으로 배분 | F6: 국민DR 89,973고객 · 육지 플러스DR 43,061고객 · 제주 플러스DR 1,573고객 | G6: S35 제12.1.3조 · S33 p.6 | H6: 확정
A7: 전력거래소 시장 (사업장용) | B7: 동일 | C7: 해당 없음 — 표준DR(10MW~), 중소형DR(2MW~), 제주DR, 휴일DR, 주파수DR, EV충전자원(충전사업자) | D7: 수요관리사업자 집합 자원 | E7: 기본정산금(원/kW-월) + 실적정산금(SMP/MGP 기준) | F7: 27개 사업자 · 75자원 · 3,877고객 · 4,239MW | G7: S35 제12.2.2조 · S33 p.3 | H7: 확정
A8: 한전 긴급절전 수요조정 | B8: 한전 (선택공급약관 제3장) | C8: 해당 없음 — 고압 일반·교육·산업용, 500kW 이상 감축 가능 고객(제주 100kW) | D8: 한전과 1년 약정 | E8: 기본지원 500원/kW·년(12월 일괄) + 실적지원(별표4, 이행률별) | F8: — | G8: S34 제28·34조 | H8: 확정
A9: 한전 주택용 에너지캐시백 | B9: 한전 (세칙 제48조의6) | C9: 해당 — 주택용 전 가구. DR이 아니라 월 사용량 절감 보상 | D9: 한전ON 신청 | E9: 절감률 구간별 30~120원/kWh(2026.7~12 한시), 여름 저녁 500원/kWh(월 1만원 한도, 종료) | F9: — | G9: A2 제48조의6 | H9: 확정
A10: 가정 HEMS가 실제로 붙일 수 있는 DR 신호는 두 개다: ① 국민DR — "지금 1시간 줄여라" (영업일 06~21시, 30분 전 통보) ② 플러스DR — "지금 더 써라" (태양광 잉여 시 9~18시, 하루 전 낙찰). 나머지는 사업장·발전기·대형 충전사업자용이다.
A12: B. DR 종류 비교표 — 전력시장운영규칙 제12장 기준
A13: 항목 | B13: 국민DR | C13: 플러스DR | D13: 표준DR | E13: 중소형DR | F13: 제주DR | G13: 휴일DR (H-표준·중소형·제주) | H13: 주파수DR | I13: EV충전자원 | J13: 한전 긴급절전 (참고)
A14: 한 줄 정의 | B14: 가정·소규모 고객이 요청 시 1시간 단위로 전기를 줄이면 보상 | C14: 재생에너지 잉여 시 전기를 더 쓰면 보상 (전력부하증대량 거래) | D14: 대형 사업장 집합 자원. 의무감축 + 자발적 입찰 | E14: 중소 사업장 집합 자원 | F14: 제주 지역 사업장 자원 | G14: 봄·가을 휴일 낮에만 참여하는 자원 (2025.3 신설) | H14: 주파수 하락 시 자동 차단되는 부하 | I14: 충전사업자용 EV 요금 사용 충전기를 묶은 자원 (2025.12.8 신설) | J14: 한전 요청 시 500kW 이상 감축하는 약정
A15: 근거 조문 | B15: 제12.1.1조 4호 | C15: 제12.1.1조 6호, 제12.7절 | D15: 제12.1.1조 1호 | E15: 제12.1.1조 2호 | F15: 제12.1.1조 3호 | G15: 제12.1.1조 7~9호 | H15: 제12.1.1조 5호 | I15: 제12.1.1조 31호 | J15: 선택공급약관 제26~36조
A16: 신설 | B16: 2019.11.7 | C16: 2021.1.1 제주 → 2024.3.28 육지 | D16: 2014.11.3 | E16: 2016.12.30 | F16: 2022.5.31 | G16: 2025.2.11 | H16: 2020.11.1 | I16: 2025.12.8 | J16: —
A17: 참여 가능 고객 | B17: 계약전력 200kW 이하 고객 + 주택용 전 가구 + 집합건물 개별세대. 단, 충전사업자용 EV 요금 사용자 제외 | C17: 판매사업자·구역전기사업자 고객, 직접구매자 (규모 제한 없음) | D17: 판매사업자·구역전기 고객, 직접구매자 | E17: 동일. 단, 계약용량 2MW 초과 산업용 제외 | F17: 제주 지역 고객 | G17: 표준/중소형/제주와 동일 기준 | H17: 주파수연계 감축이 가능한 부하 | I17: 중소형DR·제주DR 중 충전사업자용 EV 요금 사용자 | J17: 고압 일반·교육·산업용, 원격검침 가능, 500kW 이상 감축
A18: 지역 구분 | B18: 수도권 / 비수도권 / 제주권 | C18: 육지권(세부 지역별 등록) / 제주권 | D18: 수도권 / 비수도권 | E18: 수도권 / 비수도권 | F18: 제주권 | G18: 표준·중소형: 수도권/비수도권, 제주: 제주권 | H18: 육지권 | I18: 자원 유형에 따름 | J18: 전국 (제주는 100kW 기준)
A19: 자원 규모 요건 | B19: 제한 없음 (고객 10개 이상) | C19: 제한 없음 (고객 1개 이상, 입찰 최소 0.01MWh) | D19: 의무감축 10MW 초과 ~ 500MW (고객 10개 이상) | E19: 2MW 초과 ~ 50MW (고객 10개 이상) | F19: 2MW 초과 ~ 500MW | G19: 표준·중소형·제주와 동일 | H19: 감축예상용량 1MW 이상 (고객 1개 이상) | I19: 1MW 초과 ~ 50MW | J19: A형 3,000kW 또는 CBL 20% / B형 500kW
A20: 발령·거래 시간 | B20: 영업일 06~21시, 1시간 단위, 비연속 발령, 감축시작 30분 전 통보. 미발령 월은 월 1회 감축시험(1시간) | C20: 매일 09~18시 입찰. 제주: 하루전에너지가격 0원 이하 + 출력제어량 기준 초과 시 낙찰. 육지: 기준 태양광이용률·수요구간별 증대필요량 | D20: 영업일 09~20시(12~13시 제외), 60분 전 통보 | E20: 동일 | F20: 영업일 10~21시 | G20: 봄(3~5월·설 연휴)·가을(9~11월) 휴일 10~17시 | H20: 기준주파수 59.85/59.80/59.65/59.60/59.40Hz 단계별 자동 | I20: 중소형/제주DR 규칙 준용 | J20: 1시간 전 예고, 1일 1~4시간
A21: 기준부하(CBL) | B21: 별표28 방식 중 전력거래소가 매월 지정(Mid(4/6), Mid(8/10) 등). 자원 단위로 합산 산정 | C21: 전력거래기간 전 KPX 지정 (Mid(4/6), 휴일은 H-Mid(4/6)) | D21: 사업자가 고객별 선택 (Max(4/5), Mid(6/10) 등) | E21: 동일 | F21: 동일 | G21: 동일 | H21: Past(10min): 직전 10분 사용량 기준 | I21: 자원 단위 합산 | J21: 직전 영업일 10일 중 최고·최저 2일 제외 6일 평균
A22: 정산 구조 | B22: 실적급 단가 × 감축량. 실적급 단가 = 연간 기본정산금 단가(RBP, 원/kW) ÷ 최대감축시간(MRT) + MGP. 기본정산금 없음 | C22: 증대량 × 단가(원/kWh). 2025년 육지 50원, 제주 95~97원 | D22: 기본정산금(원/kW-월, 고정+차등) + 실적정산금(SMP·MGP). 위약금 있음 | E22: 동일 | F22: 동일 | G22: 고정기본정산금만 (여름·겨울 미운영) | H22: 원/kW-10분 단가 + 운전유지비 | I22: 중소형/제주DR 준용 | J22: 기본 500원/kW·년 + 실적(별표4)
A23: 2025년 단가 (KPX 공표) | B23: 육지 RBP 67,277원/kW (12월 67,253), 제주 76,562원/kW. 실적 평균 ≈ 1,625원/kWh (2025 정산금 12.97억 ÷ 798,187kWh) | C23: 육지 50원/kWh, 제주 96~97원/kWh | D23: 고정기본정산금 2025.12 2,862원/kW-월 (1~12월 862~3,075) | E23: 표준과 동일 | F23: 3,526원/kW-월 (1,095~3,835) | G23: 598~972원/kW-월 (9~11월) | H23: 39,519~41,555원/kW-10m | I23: — | J23: 기본 500원/kW·년
A24: 2026.2 참여 현황 | B24: 12개 사업자 · 214자원 · 89,973고객 | C24: 육지 10사업자·172자원·43,061고객·2,110MW / 제주 7사업자·26자원·1,573고객 | D24: 수도권 609MW·555고객, 비수도권 3,183MW·1,240고객 | E24: 수도권 185MW·753고객, 비수도권 241MW·1,257고객 | F24: 22MW·72고객 | G24: (겨울 미운영) 11차 956MW·121고객 | H24: 1단계 639MW·58고객, 3단계 278MW·30고객 | I24: (신설, 별도 통계 없음) | J24: —
A25: 2025년 실적 | B25: 45시간 발령 · 798,187kWh 감축 · 정산금 12.97억원 (누적 2020~25: 304회, 978MWh, 16.1억) | C25: 육지: 16일 63시간 30,725MWh 13.1억원 (3~6월). 제주: 표에 2023년까지만 수록 | D25: 자발적DR 연간 낙찰 15만MWh대, 신뢰성 감축시험 4,209~4,945MWh/회 | G25: 2025.9 1,081MWh | H25: 2025 운전유지비 18.6억 | I25: — | J25: —
A26: 다른 DR과 중복 등록 | B26: 불가 (1고객 1자원 원칙) | C26: 가능 — 플러스DR 고객은 다른 자원과 중복 등록 허용 | D26: 불가 | E26: 불가 | F26: 불가 | G26: 가능 | H26: 가능(양수 제외) | I26: 불가 | J26: 긴급절전은 시장 DR과 중복 참여 가능(제12.2.3조 ③3 예외)
A27: 가정 HEMS 관련성 | B27: ★ 핵심. 주택용은 자동으로 자격 충족. 히트펌프·EV·온수기 1시간 지연이 곧 감축량 | C27: ★ 핵심. EV 충전·ESS 충전·온수/축열 사전 가동을 잉여 시간으로 이동 | D27: 없음 | E27: 없음 (아파트 공용부 정도) | F27: 없음 | G27: 없음 | H27: 없음 | I27: 아파트 충전사업자 통해 간접 관련 | J27: 없음
A28: "2025년 단가" 행의 국민DR 평균 1,625원/kWh는 KPX 연간 정산금÷감축량으로 역산한 값(노랑)이다. 실제 고객이 받는 금액은 수요관리사업자가 이 정산금에서 운영비를 떼고 배분하므로 더 작다(사업자 계약별, 공통값 없음). 2026년 RBP·MRT는 KPX가 매월 공표하는 현황 보고서로 갱신할 것.
A30: C. 국민DR (에너지쉼표) — 가정 HEMS가 붙는 감축 신호
A31: 항목 | B31: 내용 | C31: 근거 | D31: 상태
A32: 참여 자격 | B32: ① 계약전력 200kW 이하 고객(상가·소규모 사업장 포함) ② 계약종별 주택용 전 가구 ③ 집합건물(아파트) 개별세대. 충전사업자용 EV 요금 사용자는 제외 | C32: S35 제12.1.1조 4호 (2025.12.8 개정) | D32: 확정
A33: 참여 경로 | B33: 가정은 KPX와 직접 거래 불가(전력거래자 등록 요건: 지능형전력망법 수요반응관리서비스제공사업자 등록증 등 — 사업자만 가능). 수요관리사업자(2026.2 기준 12개)가 국민DR 자원을 등록하고 고객을 모집. 고객은 사업자 앱에서 가입 → 사업자가 KPX에 고객 등록. 등록 신청은 매월 15~20일, 익월 1일부터 거래 적용 | C33: S35 제12.2.2조 ①3, 제12.2.3조 ①2 | D33: 확정
A34: 전력거래기간 | B34: 홀수년 12.1 ~ 다다음해 11.30 (2년). 현재 기간: 2025.12.1 ~ 2027.11.30 | C34: S35 제12.2.2조 ①3 | D34: 확정
A35: 자원 구성 | B35: 지역별(수도권/비수도권/제주권) 1개 자원에 고객 10개 이상. 의무감축용량 제한 없음. 1고객 1자원 원칙 → 국민DR 고객이 다른 국민DR 자원에 중복 가입 불가, 단 플러스DR 고객으로는 중복 가능 | C35: S35 제12.2.2조 ③, 제12.2.3조 ③2 | D35: 확정
A36: 발령 규칙 | B36: 영업일(토·공휴일 제외) 06:00~21:00 사이, 감축시작·종료는 매시 정각·15·30·45분에 발령 가능, 감축시작 최소 30분 전 통보, 일일 발령은 비연속. 플러스DR 증대 요청 시간과는 겹치지 않게 발령 | C36: S35 제12.4.3.1조 ①2·② | D36: 확정
A37: 감축시험 | B37: 매월 20일 기준 그 달에 의무감축요청이 없었으면 마지막 영업일까지 1회 시행, 감축지속시간 1시간. 실적정산금은 정상 발령과 구분 정산 | C37: S35 제12.3.2.1조 ①3·④ | D37: 확정
A38: 기준부하(CBL) | B38: 별표28 방식 중 KPX가 매월 시작 영업일 2일 전까지 지정·공지 (국민DR 적용 가능: Mid(4/6) = 최근 영업일 6일 중 최대·최소 1일 제외 4일 평균, Mid(8/10) = 10일 중 최대·최소 1일 제외 8일 평균). 자원 단위로 참여 고객 사용량을 합산해 산정. 데이터 누락 고객은 제외하고 산정 | C38: S35 제12.5.2.1조 ①2, 별표28 1.3·1.4 | D38: 확정
A39: 감축량 평가 | B39: 자원 CBL − 참여 고객의 감축시간 사용량 합. 사업자는 발령 후 영업일 5일 내 참여 고객 목록 제출 | C39: S35 제12.5.2.3조 ①2, 제12.5.2.1조 ①2다 | D39: 확정
A40: 정산 (KPX → 사업자) | B40: 기본정산금 없음. 실적정산금 = 감축이행량 × {RBP(연간 기본정산금 단가, 원/kW) ÷ MRT(최대감축시간) + MGP(당시 최고 변동비)} × 반응시간 가중치. 2025년 RBP: 육지 67,277원/kW, 제주 76,562원/kW | C40: S35 별표26 2.가, S33 p.11 | D40: 확정
A41: 실제 평균 정산 단가 | B41: 2025년: 1,297,300천원 ÷ 798,187kWh ≈ 1,625원/kWh. 2025.12.17 18시 발령: 22,221kWh → 34,369천원(1,547원/kWh). 2025.12.29 11시: 13,039kWh → 20,136천원 | C41: S33 p.18~19 (역산) | D41: 추정(계산식 병기)
A42: 고객 보상 (사업자 → 가정) | B42: 사업자 계약에 따라 현금·포인트·마일리지·기부 등. 공통 단가 없음. 과거 홍보자료는 "kWh당 1,300원(2022)", "1,600원(2022 기준)" 등으로 안내. 삼성 SmartThings·LG ThinQ 연동으로 자동 참여하는 사업자(파란에너지 등) 있음 | C42: S36·S37 | D42: 확인필요(사업자별)
... A44: HEMS 설계 포인트 | B44: ① 발령은 1시간·30분 전이므로 히트펌프 예열/온수 선가동 → 발령 시 OFF, EV 충전 일시정지, ESS 방전이 감축량이 됨 ② CBL이 "최근 영업일 평균"이라 평소 사용량이 낮은 집은 감축량이 작게 나옴 ③ 06~21시 영업일만 → 주말·야간 자동화는 국민DR과 무관 ④ 캐시백(월 절감)과 국민DR(시간 절감)은 별개로 둘 다 가능 | C44: 설계 판단 | D44: 추정
...

Sheet ESS_DR_인센티브
A1: ESS 요금 특례 · DR · 에너지캐시백
A2: HEMS 수익·절감 레버 관점 정리
A4: A. ESS 요금 할인 특례 연혁
A5: 기간 | B5: 충전 전력량요금 | C5: 기본요금 | D5: 대상 | E5: 현재 상태 | F5: 근거
A6: ~2020.12 | B6: 경부하 충전 50% 할인 | C6: 피크감축량의 3배 할인 | D6: 계시별 적용 일반용·산업용·교육용 (피크저감용 ESS) | E6: 종료 (단, ESS 가동중단 손실보전위원회 의결 대상 고객은 존속기간 ~2026.3 내에서 구 할인 유지 — 세칙 부칙 2020.12.17 제5호) | F6: A2 부칙·S19
A7: 2021.1~2026.3.31 | B7: 할인 폐지 | C7: 피크감축량 1배 할인 + 계절별 지정 3시간 방전 시 인정배수 1.1~1.34배 | D7: 동일 (충전율 옥내 80%·옥외 90% 준수 조건) | E7: 종료 확정 — 2026.8.1판 세칙 별표4 제9호 '기본요금 할인은 2016.4.1부터 2026.3.31까지 적용', 연장 규정 없음 | F7: A2 별표4 제9호·S18·S19
A8: 주택용 | B8: - | C8: - | D8: 주택용 ESS 전용 요금 특례 없음 | E8: 해당 없음 | F8: S26
A9: 시사점: 주택 HEMS에서 ESS의 경제성은 요금특례가 아니라 (1) 태양광 잉여 저장·자가소비로 순 수전량을 줄여 누진 3단계 진입을 피하는 것(계통 충전→방전만으로는 월 누적 kWh가 줄지 않고 손실만 증가), (2) 제주·히트펌프 가구의 계시별 차익, (3) 에너지캐시백·DR 보상에서 나온다. 산업·상업 ESS 특례는 2026.3.31로 종료되었으므로 할인 수익을 사업성에 넣지 말 것.
A11: B. 2026 에너지캐시백 (주택용, 2026.7~12)
A12: 프로그램 | B12: 기간·시간 | C12: 조건 | D12: 보상 단가 | E12: HEMS 연계 | F12: 근거
A13: 기본 에너지캐시백 | B13: 2026.7~12 (월 단위) | C13: 전년 대비 1% 이상 절감(기존 3%에서 완화) | D13: 최대 120원/kWh | E13: 월간 사용량 관리 | F13: S20
A14: 여름 저녁 피크 절감 | B14: 7~8월 평일 17~20시 (2026.7.1~8.31 한시, 종료) | C14: 직전 2년 동시간대 평균 대비 절감, 시간별 원격검침 필요 | D14: 500원/kWh, 월 지급한도 10,000원 | E14: 저녁 부하 이동·ESS 방전 | F14: A2 제48조의6·S20
A15: 스마트가전 캐시백(시범) | B15: 9~10월 주말·공휴일 11~14시 | C15: SmartThings·LG ThinQ 등록 세탁기·건조기·식기세척기·스타일러 | D15: 100원/kWh | E15: ThinQ 연동 가전 낮 시간 가동 유도 | F15: S20
A17: C. 지역 특화 제도 — DR 상세는 DR_수요반응 시트 참조
A18: 제도 | B18: 지역 | C18: 내용 | D18: 상태 | F18: 근거
A19: 플러스DR | B19: 육지·제주 (2021.1 제주 신설 → 2024.3 육지 신설) | C19: 재생에너지 출력제어가 예상될 때 전력 소비를 늘리면 보상. 제주는 2022.5부터 수요자원시장 분리 운영, 2023 전기차 충전 할인 등으로 확대. 육지권도 2024.3부터 플러스DR 자원 등록 가능 | D19: 시장 운영 중(전력거래소 2026 사업실명제, 전력시장운영규칙 2026.7.24판). 가구 실수령 단가는 집합사업자 계약·이행량·시장정산에 따르므로 공통값 없음 | F19: S25·S32
A20: 산업용 지역별 차등요금 | B20: 육지 11개 지역 (제주 제외) | C20: 수도권 남부 ±1원, 수도권 북부 최대 10원, 중부권 최대 15원, 남부권 최대 18원/kWh 인하 | D20: 2026년 내 도입 예정(주택용 제외) | F20: S16

Sheet 출처
A1: 근거 자료 목록
A2: 등급 A=정부·한전 1차자료 / B=주요 언론·공공기관 게재 / C=블로그·위키 등 2차 정리 (C등급 단독 근거 항목은 '확인필요')
A4: ID | B4: 자료명 | C4: 발행·게재 | D4: 일자 | E4: 등급 | F4: URL
A5: A1 | B5: 한전 기본공급약관 및 시행세칙 (2026.8.1 발행) — 별표1 월간 전기요금표(2026.6.1 적용), 별표3 계절별·시간대별 구분표, 별표7 기후환경요금, 별표8 연료비조정요금, 제56~67조, 부칙 | C5: 한국전력공사 | D5: 2026-08-01 | E5: A | F5: 프로젝트 문서: 기본공급약관 및 시행세칙(260801).pdf
A6: S01 | B6: 낮엔 낮추고 저녁은 높인다… 계절·시간대별 전기요금 개편안 시행 (보도자료) | C6: 기후에너지환경부 | D6: 2026-04 | E6: A | F6: https://mcee.go.kr/home/web/board/read.do?boardCategoryId=&boardId=1857140&boardMasterId=939&menuId=10598
A7: S02 | B7: 산업용 전기료, 낮 시간 최대 16.9원↓…봄·가을 주말 낮 50% 할인 | C7: 대한민국 정책브리핑 | D7: 2026-03-13 | E7: A | F7: https://www.korea.kr/news/policyNewsView.do?newsId=148960823
A8: S03 | B8: 봄·가을 주말과 공휴일 낮 전력량요금 50%↓…16일부터 적용 | C8: 대한민국 정책브리핑 | D8: 2026-04 | E8: A | F8: https://www.korea.kr/news/policyNewsView.do?newsId=148962675
A9: S04 | B9: 계절·시간대별 전기요금 개편안 시행 (부처 브리핑) | C9: 대한민국 정책브리핑 | D9: 2026-04 | E9: A | F9: https://www.korea.kr/briefing/policyBriefingView.do?newsId=156755866
A10: S05 | B10: 전기요금표 (2025.04.01 시행) — 공공요금 거래가격 자료 | C10: 한국물가정보(data.cmpi.or.kr) 게재, 한전 요금표 전재 | D10: 2025-04-01 | E10: B | F10: https://data.cmpi.or.kr/program/board/2025.04.01%20%EC%8B%9C%ED%96%89.pdf
A11: S06 | B11: 2026년 4월 16일 전기요금 개편안 시행 정보 정리 (개편 전·후 시간대표) | C11: (주)명군전력 | D11: 2026-04 | E11: C | F11: https://myunggun.com/2026%EB%85%84-4%EC%9B%94-16%EC%9D%BC-%EC%A0%84%EA%B8%B0%EC%9A%94%EA%B8%88-%EA%B0%9C%ED%8E%B8%EC%95%88-%EC%8B%9C%ED%96%89-%EC%A0%95%EB%B3%B4-%EC%A0%95%EB%A6%AC/
A12: S07 | B12: 3분기 연료비조정단가도 1kWh당 5원 유지 | C12: ZDNet Korea | D12: 2026-06-22 | E12: B | F12: https://zdnet.co.kr/view/?no=20260622094221
A13: S08 | B13: 3분기 전기요금 동결…가정용 13분기 연속 | C13: 이데일리 | D13: 2026-06-22 | E13: B | F13: https://edaily.co.kr/News/Read?mediaCodeNo=257&newsId=02027046645484344
A14: S09 | B14: 전력기금 요율 3.7%서 2.7%로 단계적 인하 결정 | C14: 전기신문 | D14: 2024-03 | E14: B | F14: https://www.electimes.com/news/articleView.html?idxno=334694
A15: S10 | B15: 제주지역 계절별·시간별 요금제 시간대 개편 | C15: 에너지신문 | D15: 2021-06 | E15: B | F15: https://www.energy-news.co.kr/news/articleView.html?idxno=77182
... A44: S38 | B44: 낮에 충전하면 요금 할인, 전력거래소 플러스DR로 전기차 유지비 잡는다 (플러스DR과 한전 주말할인을 혼용 서술 — 교차확인용) | C44: Businesskorea | D44: 2026 | E44: B | F44: https://www.businesskorea.co.kr/news/articleView.html?idxno=273132
